Workbook

Sheet Welcome - Instructions
A1: Interior Design Project Management Workbook
A3: Quick Start Guide
A4: Step 1: Add client/project details in Client & Project Profile. Step 2: Add rooms in Room List. Step 3: Add FF&E items in Master FF&E Schedule. Step 4: Track budget, orders, approvals, delivery, and installation. Step 5: Use Project Dashboard for overview.
A7: What Each Tab Is Used For
A8: Profile stores project details. Room List tracks rooms and budgets. Master FF&E is the core item schedule. Other tabs track furniture, fixtures, finishes, sourcing, vendors, budget, orders, delivery, approvals, timeline, tasks, measurements, contractors, invoices, and notes.
A11: How To Enter Data
A12: Type into white cells beginning on row 2. Header rows and formula columns should not be overwritten unless you intentionally customize the workbook.
A15: Color Coding
A16: Green = complete / approved / on budget. Yellow = pending / in progress. Red = overdue / over budget / delayed. Gray = cancelled / on hold.
A19: Dropdown Instructions
A20: Click cells in status/category/room/vendor/priority columns and select from dropdown menus. Room and vendor dropdowns reference the Room List and Vendor Database.
A23: Compatibility Note
... A32: Add your support email, shop URL, license terms, or client handoff notes here before selling or sharing.

Sheet Project Dashboard
A1: Project Dashboard
A3: Total project budget | D3: Total estimated cost | G3: Total actual cost | J3: Remaining budget
A4: ='Client & Project Profile'!B12 | D4: =SUM('Budget Tracker'!C2:C251) | G4: =SUM('Budget Tracker'!D2:D251) | J4: ='Client & Project Profile'!B12-SUM('Budget Tracker'!D2:D251)
A6: Budget used % | D6: Number of rooms | G6: Total FF&E items | J6: Items approved
A7: =IFERROR(SUM('Budget Tracker'!D2:D251)/'Client & Project Profile'!B12,0) | D7: =COUNTA('Room List'!A2:A251) | G7: =COUNTA('Master FF&E Schedule'!D2:D251) | J7: =COUNTIF('Master FF&E Schedule'!W2:W251,"Approved")
A9: Items ordered | D9: Items delivered | G9: Items installed | J9: Overdue tasks
A10: =COUNTIF('Master FF&E Schedule'!V2:V251,"Ordered")+COUNTIF('Master FF&E Schedule'!V2:V251,"Confirmed")+COUNTIF('Master FF&E Schedule'!V2:V251,"In production")+COUNTIF('Master FF&E Schedule'!V2:V251,"Shipped")+COUNTIF('Master FF&E Schedule'!V2:V251,"Delivered") | D10: =COUNTIF('Master FF&E Schedule'!X2:X251,"Delivered") | G10: =COUNTIF('Master FF&E Schedule'!Y2:Y251,"Installed") | J10: =COUNTIF('Task & To-Do List'!I2:I251,">0")+COUNTIF('Project Timeline'!L2:L251,">0")
A12: Pending client approvals | D12: Open vendor orders | G12: Items not ordered | J12: Delivered not installed
A13: =COUNTIF('Client Approval Tracker'!F2:F251,"Sent")+COUNTIF('Client Approval Tracker'!F2:F251,"Not sent")+COUNTIF('Master FF&E Schedule'!W2:W251,"Client review") | D13: =COUNTIF('Purchase Order Tracker'!J2:J251,"Ordered")+COUNTIF('Purchase Order Tracker'!J2:J251,"Confirmed")+COUNTIF('Purchase Order Tracker'!J2:J251,"In production")+COUNTIF('Purchase Order Tracker'!J2:J251,"Shipped")+COUNTIF('Purchase Order Tracker'!J2:J251,"Delayed") | G13: =COUNTIF('Master FF&E Schedule'!V2:V251,"Not ordered")+COUNTIFS('Master FF&E Schedule'!D2:D251,"<>",'Master FF&E Schedule'!V2:V251,"") | J13: =COUNTIFS('Master FF&E Schedule'!X2:X251,"Delivered",'Master FF&E Schedule'!Y2:Y251,"<>Installed")
A16: Budget by Room | E16: Budget vs Actual | H16: Item Status Breakdown
A17: Room | B17: Estimated | C17: Actual | E17: Metric | F17: Amount | H17: Status | I17: Count
A18: ='Room List'!A2 | B18: ='Room List'!G2 | C18: ='Room List'!H2 | E18: Budget | F18: ='Client & Project Profile'!B12 | H18: Sourcing | I18: =COUNTIF('Master FF&E Schedule'!V2:Y251,"Sourcing")
A19: ='Room List'!A3 | B19: ='Room List'!G3 | C19: ='Room List'!H3 | E19: Actual | F19: =SUM('Budget Tracker'!D2:D251) | H19: Option selected | I19: =COUNTIF('Master FF&E Schedule'!V2:Y251,"Option selected")
A20: ='Room List'!A4 | B20: ='Room List'!G4 | C20: ='Room List'!H4 | H20: Client review | I20: =COUNTIF('Master FF&E Schedule'!V2:Y251,"Client review")
A21: ='Room List'!A5 | B21: ='Room List'!G5 | C21: ='Room List'!H5 | H21: Approved | I21: =COUNTIF('Master FF&E Schedule'!V2:Y251,"Approved")
A22: ='Room List'!A6 | B22: ='Room List'!G6 | C22: ='Room List'!H6 | H22: Ordered | I22: =COUNTIF('Master FF&E Schedule'!V2:Y251,"Ordered")
A23: ='Room List'!A7 | B23: ='Room List'!G7 | C23: ='Room List'!H7 | H23: Shipped | I23: =COUNTIF('Master FF&E Schedule'!V2:Y251,"Shipped")
A24: ='Room List'!A8 | B24: ='Room List'!G8 | C24: ='Room List'!H8 | H24: Delivered | I24: =COUNTIF('Master FF&E Schedule'!V2:Y251,"Delivered")
A25: ='Room List'!A9 | B25: ='Room List'!G9 | C25: ='Room List'!H9 | H25: Installed | I25: =COUNTIF('Master FF&E Schedule'!V2:Y251,"Installed")
A26: ='Room List'!A10 | B26: ='Room List'!G10 | C26: ='Room List'!H10 | H26: Cancelled | I26: =COUNTIF('Master FF&E Schedule'!V2:Y251,"Cancelled")
A27: ='Room List'!A11 | B27: ='Room List'!G11 | C27: ='Room List'!H11 | H27: Backordered | I27: =COUNTIF('Master FF&E Schedule'!V2:Y251,"Backordered")
A28: ='Room List'!A12 | B28: ='Room List'!G12 | C28: ='Room List'!H12
A29: ='Room List'!A13 | B29: ='Room List'!G13 | C29: ='Room List'!H13
A30: ='Room List'!A14 | B30: ='Room List'!G14 | C30: ='Room List'!H14
A35: Delivery Status Breakdown | E35: Category Spend Breakdown
A36: Status | B36: Count | E36: Category | F36: Final Cost
A37: Not ordered | B37: =COUNTIF('Delivery & Installation'!G2:G251,"Not ordered") | E37: Sofa | F37: =SUMIF('Master FF&E Schedule'!C2:C251,"Sofa",'Master FF&E Schedule'!T2:T251)
A38: Ordered | B38: =COUNTIF('Delivery & Installation'!G2:G251,"Ordered") | E38: Chair | F38: =SUMIF('Master FF&E Schedule'!C2:C251,"Chair",'Master FF&E Schedule'!T2:T251)
A39: Shipped | B39: =COUNTIF('Delivery & Installation'!G2:G251,"Shipped") | E39: Table | F39: =SUMIF('Master FF&E Schedule'!C2:C251,"Table",'Master FF&E Schedule'!T2:T251)
A40: Delivered | B40: =COUNTIF('Delivery & Installation'!G2:G251,"Delivered") | E40: Bed | F40: =SUMIF('Master FF&E Schedule'!C2:C251,"Bed",'Master FF&E Schedule'!T2:T251)
A41: Delayed | B41: =COUNTIF('Delivery & Installation'!G2:G251,"Delayed") | E41: Rug | F41: =SUMIF('Master FF&E Schedule'!C2:C251,"Rug",'Master FF&E Schedule'!T2:T251)
A42: Cancelled | B42: =COUNTIF('Delivery & Installation'!G2:G251,"Cancelled") | E42: Lighting | F42: =SUMIF('Master FF&E Schedule'!C2:C251,"Lighting",'Master FF&E Schedule'!T2:T251)
A43: Returned | B43: =COUNTIF('Delivery & Installation'!G2:G251,"Returned") | E43: Artwork | F43: =SUMIF('Master FF&E Schedule'!C2:C251,"Artwork",'Master FF&E Schedule'!T2:T251)
A44: Backordered | B44: =COUNTIF('Delivery & Installation'!G2:G251,"Backordered") | E44: Mirror | F44: =SUMIF('Master FF&E Schedule'!C2:C251,"Mirror",'Master FF&E Schedule'!T2:T251)
E45: Window treatment | F45: =SUMIF('Master FF&E Schedule'!C2:C251,"Window treatment",'Master FF&E Schedule'!T2:T251)
E46: Hardware | F46: =SUMIF('Master FF&E Schedule'!C2:C251,"Hardware",'Master FF&E Schedule'!T2:T251)
E47: Plumbing fixture | F47: =SUMIF('Master FF&E Schedule'!C2:C251,"Plumbing fixture",'Master FF&E Schedule'!T2:T251)
E48: Appliance | F48: =SUMIF('Master FF&E Schedule'!C2:C251,"Appliance",'Master FF&E Schedule'!T2:T251)
E49: Decor | F49: =SUMIF('Master FF&E Schedule'!C2:C251,"Decor",'Master FF&E Schedule'!T2:T251)
E50: Textile | F50: =SUMIF('Master FF&E Schedule'!C2:C251,"Textile",'Master FF&E Schedule'!T2:T251)
...

Sheet Client & Project Profile
A1: Client & Project Profile
A3: Client name
A4: Client email
A5: Phone number
A6: Project name
A7: Project address
A8: Project type | B8: Residential
A9: Design style
A10: Start date
A11: Target completion date
A12: Total budget | B12: 0
A13: Designer name
A14: Client notes
A15: Scope summary
A16: Project status | B16: In progress
A17: Contract signed | B17: No
A18: Deposit paid | B18: No
A19: Design package selected
A20: Billing method | B20: Flat fee

Sheet Room List
A1: Room name | B1: Room type | C1: Floor/level | D1: Square footage | E1: Design status | F1: Budget allocation | G1: Estimated spend | H1: Actual spend | I1: Remaining budget | J1: Priority level | K1: Notes
G2: =IFERROR(SUMIF('Master FF&E Schedule'!$B:$B,$A2,'Master FF&E Schedule'!$P:$P),0) | H2: =IFERROR(SUMIF('Master FF&E Schedule'!$B:$B,$A2,'Master FF&E Schedule'!$T:$T),0) | I2: =IF($A2="","",$F2-$H2)
G3: =IFERROR(SUMIF('Master FF&E Schedule'!$B:$B,$A3,'Master FF&E Schedule'!$P:$P),0) | H3: =IFERROR(SUMIF('Master FF&E Schedule'!$B:$B,$A3,'Master FF&E Schedule'!$T:$T),0) | I3: =IF($A3="","",$F3-$H3)
G4: =IFERROR(SUMIF('Master FF&E Schedule'!$B:$B,$A4,'Master FF&E Schedule'!$P:$P),0) | H4: =IFERROR(SUMIF('Master FF&E Schedule'!$B:$B,$A4,'Master FF&E Schedule'!$T:$T),0) | I4: =IF($A4="","",$F4-$H4)
G5: =IFERROR(SUMIF('Master FF&E Schedule'!$B:$B,$A5,'Master FF&E Schedule'!$P:$P),0) | H5: =IFERROR(SUMIF('Master FF&E Schedule'!$B:$B,$A5,'Master FF&E Schedule'!$T:$T),0) | I5: =IF($A5="","",$F5-$H5)
G6: =IFERROR(SUMIF('Master FF&E Schedule'!$B:$B,$A6,'Master FF&E Schedule'!$P:$P),0) | H6: =IFERROR(SUMIF('Master FF&E Schedule'!$B:$B,$A6,'Master FF&E Schedule'!$T:$T),0) | I6: =IF($A6="","",$F6-$H6)
G7: =IFERROR(SUMIF('Master FF&E Schedule'!$B:$B,$A7,'Master FF&E Schedule'!$P:$P),0) | H7: =IFERROR(SUMIF('Master FF&E Schedule'!$B:$B,$A7,'Master FF&E Schedule'!$T:$T),0) | I7: =IF($A7="","",$F7-$H7)
G8: =IFERROR(SUMIF('Master FF&E Schedule'!$B:$B,$A8,'Master FF&E Schedule'!$P:$P),0) | H8: =IFERROR(SUMIF('Master FF&E Schedule'!$B:$B,$A8,'Master FF&E Schedule'!$T:$T),0) | I8: =IF($A8="","",$F8-$H8)
G9: =IFERROR(SUMIF('Master FF&E Schedule'!$B:$B,$A9,'Master FF&E Schedule'!$P:$P),0) | H9: =IFERROR(SUMIF('Master FF&E Schedule'!$B:$B,$A9,'Master FF&E Schedule'!$T:$T),0) | I9: =IF($A9="","",$F9-$H9)
G10: =IFERROR(SUMIF('Master FF&E Schedule'!$B:$B,$A10,'Master FF&E Schedule'!$P:$P),0) | H10: =IFERROR(SUMIF('Master FF&E Schedule'!$B:$B,$A10,'Master FF&E Schedule'!$T:$T),0) | I10: =IF($A10="","",$F10-$H10)
G11: =IFERROR(SUMIF('Master FF&E Schedule'!$B:$B,$A11,'Master FF&E Schedule'!$P:$P),0) | H11: =IFERROR(SUMIF('Master FF&E Schedule'!$B:$B,$A11,'Master FF&E Schedule'!$T:$T),0) | I11: =IF($A11="","",$F11-$H11)
G12: =IFERROR(SUMIF('Master FF&E Schedule'!$B:$B,$A12,'Master FF&E Schedule'!$P:$P),0) | H12: =IFERROR(SUMIF('Master FF&E Schedule'!$B:$B,$A12,'Master FF&E Schedule'!$T:$T),0) | I12: =IF($A12="","",$F12-$H12)
G13: =IFERROR(SUMIF('Master FF&E Schedule'!$B:$B,$A13,'Master FF&E Schedule'!$P:$P),0) | H13: =IFERROR(SUMIF('Master FF&E Schedule'!$B:$B,$A13,'Master FF&E Schedule'!$T:$T),0) | I13: =IF($A13="","",$F13-$H13)
... G251: =IFERROR(SUMIF('Master FF&E Schedule'!$B:$B,$A251,'Master FF&E Schedule'!$P:$P),0) | H251: =IFERROR(SUMIF('Master FF&E Schedule'!$B:$B,$A251,'Master FF&E Schedule'!$T:$T),0) | I251: =IF($A251="","",$F251-$H251)

Sheet Master FF&E Schedule
A1: Item ID | B1: Room | C1: Category | D1: Item name | E1: Description | F1: Quantity | G1: Dimensions | H1: Material | I1: Finish | J1: Color | K1: Vendor | L1: Brand | M1: Product link | N1: SKU/model number | O1: Unit cost | P1: Total cost | Q1: Tax | R1: Shipping | S1: Discount | T1: Final cost | U1: Lead time | V1: Order status | W1: Approval status | X1: Delivery status | Y1: Install status | Z1: Notes | AA1: Image link
P2: =IF($F2="","",$F2*$O2) | T2: =IF($P2="","",$P2+$Q2+$R2-$S2)
P3: =IF($F3="","",$F3*$O3) | T3: =IF($P3="","",$P3+$Q3+$R3-$S3)
P4: =IF($F4="","",$F4*$O4) | T4: =IF($P4="","",$P4+$Q4+$R4-$S4)
P5: =IF($F5="","",$F5*$O5) | T5: =IF($P5="","",$P5+$Q5+$R5-$S5)
P6: =IF($F6="","",$F6*$O6) | T6: =IF($P6="","",$P6+$Q6+$R6-$S6)
P7: =IF($F7="","",$F7*$O7) | T7: =IF($P7="","",$P7+$Q7+$R7-$S7)
P8: =IF($F8="","",$F8*$O8) | T8: =IF($P8="","",$P8+$Q8+$R8-$S8)
P9: =IF($F9="","",$F9*$O9) | T9: =IF($P9="","",$P9+$Q9+$R9-$S9)
P10: =IF($F10="","",$F10*$O10) | T10: =IF($P10="","",$P10+$Q10+$R10-$S10)
P11: =IF($F11="","",$F11*$O11) | T11: =IF($P11="","",$P11+$Q11+$R11-$S11)
P12: =IF($F12="","",$F12*$O12) | T12: =IF($P12="","",$P12+$Q12+$R12-$S12)
P13: =IF($F13="","",$F13*$O13) | T13: =IF($P13="","",$P13+$Q13+$R13-$S13)
... P251: =IF($F251="","",$F251*$O251) | T251: =IF($P251="","",$P251+$Q251+$R251-$S251)

Sheet Furniture Schedule
A1: Room | B1: Furniture item | C1: Dimensions | D1: Quantity | E1: Vendor | F1: Product link | G1: Fabric/material | H1: Finish | I1: Cost | J1: Approval status | K1: Order status | L1: Delivery date | M1: Install date

Sheet Fixtures Schedule
A1: Room | B1: Fixture type | C1: Item name | D1: Finish | E1: Size | F1: Vendor | G1: Model/SKU | H1: Quantity | I1: Unit cost | J1: Total cost | K1: Required rough-in date | L1: Order deadline | M1: Delivery date | N1: Installer notes
J2: =IF($H2="","",$H2*$I2)
J3: =IF($H3="","",$H3*$I3)
J4: =IF($H4="","",$H4*$I4)
J5: =IF($H5="","",$H5*$I5)
J6: =IF($H6="","",$H6*$I6)
J7: =IF($H7="","",$H7*$I7)
J8: =IF($H8="","",$H8*$I8)
J9: =IF($H9="","",$H9*$I9)
J10: =IF($H10="","",$H10*$I10)
J11: =IF($H11="","",$H11*$I11)
J12: =IF($H12="","",$H12*$I12)
J13: =IF($H13="","",$H13*$I13)
... J251: =IF($H251="","",$H251*$I251)

Sheet Finishes Schedule
A1: Room | B1: Surface/application | C1: Finish type | D1: Product name | E1: Color/finish | F1: Material | G1: Vendor | H1: Product link | I1: SKU | J1: Quantity needed | K1: Unit cost | L1: Total cost | M1: Sample ordered | N1: Sample approved | O1: Installer notes
L2: =IF($J2="","",$J2*$K2)
L3: =IF($J3="","",$J3*$K3)
L4: =IF($J4="","",$J4*$K4)
L5: =IF($J5="","",$J5*$K5)
L6: =IF($J6="","",$J6*$K6)
L7: =IF($J7="","",$J7*$K7)
L8: =IF($J8="","",$J8*$K8)
L9: =IF($J9="","",$J9*$K9)
L10: =IF($J10="","",$J10*$K10)
L11: =IF($J11="","",$J11*$K11)
L12: =IF($J12="","",$J12*$K12)
L13: =IF($J13="","",$J13*$K13)
... L251: =IF($J251="","",$J251*$K251)

Sheet Product Sourcing Tracker
A1: Room | B1: Item needed | C1: Option 1 link | D1: Option 1 price | E1: Option 2 link | F1: Option 2 price | G1: Option 3 link | H1: Option 3 price | I1: Preferred option | J1: Pros | K1: Cons | L1: Client feedback | M1: Final selection

Sheet Vendor & Supplier Database
A1: Vendor name | B1: Vendor type | C1: Contact person | D1: Email | E1: Phone | F1: Website | G1: Account number | H1: Trade discount % | I1: Lead time | J1: Shipping terms | K1: Return policy | L1: Notes

Sheet Budget Tracker
A1: Budget category | B1: Budgeted amount | C1: Estimated amount | D1: Actual amount | E1: Difference | F1: Paid amount | G1: Balance due | H1: Payment status | I1: Notes
A2: Furniture | E2: =IF($A2="","",$B2-$D2) | G2: =IF($A2="","",$D2-$F2)
A3: Lighting | E3: =IF($A3="","",$B3-$D3) | G3: =IF($A3="","",$D3-$F3)
A4: Rugs | E4: =IF($A4="","",$B4-$D4) | G4: =IF($A4="","",$D4-$F4)
A5: Decor | E5: =IF($A5="","",$B5-$D5) | G5: =IF($A5="","",$D5-$F5)
A6: Artwork | E6: =IF($A6="","",$B6-$D6) | G6: =IF($A6="","",$D6-$F6)
A7: Window treatments | E7: =IF($A7="","",$B7-$D7) | G7: =IF($A7="","",$D7-$F7)
A8: Flooring | E8: =IF($A8="","",$B8-$D8) | G8: =IF($A8="","",$D8-$F8)
A9: Paint/wallcovering | E9: =IF($A9="","",$B9-$D9) | G9: =IF($A9="","",$D9-$F9)
A10: Contractor labor | E10: =IF($A10="","",$B10-$D10) | G10: =IF($A10="","",$D10-$F10)
A11: Installation | E11: =IF($A11="","",$B11-$D11) | G11: =IF($A11="","",$D11-$F11)
A12: Shipping | E12: =IF($A12="","",$B12-$D12) | G12: =IF($A12="","",$D12-$F12)
A13: Taxes | E13: =IF($A13="","",$B13-$D13) | G13: =IF($A13="","",$D13-$F13)
... A15: Contingency | E15: =IF($A15="","",$B15-$D15) | G15: =IF($A15="","",$D15-$F15)
E16: =IF($A16="","",$B16-$D16) | G16: =IF($A16="","",$D16-$F16)
E17: =IF($A17="","",$B17-$D17) | G17: =IF($A17="","",$D17-$F17)
E18: =IF($A18="","",$B18-$D18) | G18: =IF($A18="","",$D18-$F18)
E19: =IF($A19="","",$B19-$D19) | G19: =IF($A19="","",$D19-$F19)
E20: =IF($A20="","",$B20-$D20) | G20: =IF($A20="","",$D20-$F20)
E21: =IF($A21="","",$B21-$D21) | G21: =IF($A21="","",$D21-$F21)
E22: =IF($A22="","",$B22-$D22) | G22: =IF($A22="","",$D22-$F22)
E23: =IF($A23="","",$B23-$D23) | G23: =IF($A23="","",$D23-$F23)
E24: =IF($A24="","",$B24-$D24) | G24: =IF($A24="","",$D24-$F24)
E25: =IF($A25="","",$B25-$D25) | G25: =IF($A25="","",$D25-$F25)
E26: =IF($A26="","",$B26-$D26) | G26: =IF($A26="","",$D26-$F26)
E27: =IF($A27="","",$B27-$D27) | G27: =IF($A27="","",$D27-$F27)
... E251: =IF($A251="","",$B251-$D251) | G251: =IF($A251="","",$D251-$F251)
A254: Total budget | B254: =SUM(B2:B251)
A255: Total estimated | B255: =SUM(C2:C251)
A256: Total actual | B256: =SUM(D2:D251)
A257: Over/under budget | B257: =B254-B256
A258: Total paid | B258: =SUM(F2:F251)
A259: Remaining balance | B259: =SUM(G2:G251)

Sheet Purchase Order Tracker
A1: PO number | B1: Vendor | C1: Room | D1: Item | E1: Quantity | F1: Order date | G1: Expected ship date | H1: Expected delivery date | I1: Actual delivery date | J1: Order status | K1: Tracking number | L1: Carrier | M1: Invoice number | N1: Amount | O1: Paid status | P1: Notes

Sheet Delivery & Installation
A1: Item | B1: Room | C1: Vendor | D1: Delivery address | E1: Expected delivery date | F1: Actual delivery date | G1: Delivery status | H1: Received by | I1: Damage check | J1: Damage notes | K1: Storage location | L1: Install date | M1: Installer | N1: Installation status | O1: Punch list notes

Sheet Client Approval Tracker
A1: Item/design decision | B1: Room | C1: Approval type | D1: Sent to client date | E1: Client response date | F1: Status | G1: Approved option | H1: Client comments | I1: Revision needed | J1: Final approval date

Sheet Project Timeline
A1: Phase | B1: Task | C1: Assigned to | D1: Start date | E1: Due date | F1: Completion date | G1: Status | H1: Priority | I1: Dependencies | J1: Notes | K1: Duration days | L1: Days overdue | M1: Gantt W1 | N1: Gantt W2 | O1: Gantt W3 | P1: Gantt W4 | Q1: Gantt W5 | R1: Gantt W6 | S1: Gantt W7 | T1: Gantt W8 | U1: Gantt W9 | V1: Gantt W10 | W1: Gantt W11 | X1: Gantt W12
K2: =IF(OR($D2="",$E2=""),"",$E2-$D2+1) | L2: =IF(AND($E2<TODAY(),$G2<>"Complete"),TODAY()-$E2,0) | M2: =IF(OR($D2="",$E2=""),"",IF(AND($D2<=IF('Client & Project Profile'!$B$10="",TODAY(),'Client & Project Profile'!$B$10)+0*7+6,$E2>=IF('Client & Project Profile'!$B$10="",TODAY(),'Client & Project Profile'!$B$10)+0*7),"■","")) | N2: =IF(OR($D2="",$E2=""),"",IF(AND($D2<=IF('Client & Project Profile'!$B$10="",TODAY(),'Client & Project Profile'!$B$10)+1*7+6,$E2>=IF('Client & Project Profile'!$B$10="",TODAY(),'Client & Project Profile'!$B$10)+1*7),"■","")) | O2: =IF(OR($D2="",$E2=""),"",IF(AND($D2<=IF('Client & Project Profile'!$B$10="",TODAY(),'Client & Project Profile'!$B$10)+2*7+6,$E2>=IF('Client & Project Profile'!$B$10="",TODAY(),'Client & Project Profile'!$B$10)+2*7),"■","")) | P2: =IF(OR($D2="",$E2=""),"",IF(AND($D2<=IF('Client & Project Profile'!$B$10="",TODAY(),'Client & Project Profile'!$B$10)+3*7+6,$E2>=IF('Client & Project Profile'!$B$10="",TODAY(),'Client & Project Profile'!$B$10)+3*7),"■","")) | Q2: =IF(OR($D2="",$E2=""),"",IF(AND($D2<=IF('Client & Project Profile'!$B$10="",TODAY(),'Client & Project Profile'!$B$10)+4*7+6,$E2>=IF('Client & Project Profile'!$B$10="",TODAY(),'Client & Project Profile'!$B$10)+4*7),"■","")) | R2: =IF(OR($D2="",$E2=""),"",IF(AND($D2<=IF('Client & Project Profile'!$B$10="",TODAY(),'Client & Project Profile'!$B$10)+5*7+6,$E2>=IF('Client & Project Profile'!$B$10="",TODAY(),'Client & Project Profile'!$B$10)+5*7),"■","")) | S2: =IF(OR($D2="",$E2=""),"",IF(AND($D2<=IF('Client & Project Profile'!$B$10="",TODAY(),'Client & Project Profile'!$B$10)+6*7+6,$E2>=IF('Client & Project Profile'!$B$10="",TODAY(),'Client & Project Profile'!$B$10)+6*7),"■","")) | T2: =IF(OR($D2="",$E2=""),"",IF(AND($D2<=IF('Client & Project Profile'!$B$10="",TODAY(),'Client & Project Profile'!$B$10)+7*7+6,$E2>=IF('Client & Project Profile'!$B$10="",TODAY(),'Client & Project Profile'!$B$10)+7*7),"■","")) | U2: =IF(OR($D2="",$E2=""),"",IF(AND($D2<=IF('Client & Project Profile'!$B$10="",TODAY(),'Client & Project Profile'!$B$10)+8*7+6,$E2>=IF('Client & Project Profile'!$B$10="",TODAY(),'Client & Project Profile'!$B$10)+8*7),"■","")) | V2: =IF(OR($D2="",$E2=""),"",IF(AND($D2<=IF('Client & Project Profile'!$B$10="",TODAY(),'Client & Project Profile'!$B$10)+9*7+6,$E2>=IF('Client & Project Profile'!$B$10="",TODAY(),'Client & Project Profile'!$B$10)+9*7),"■","")) | W2: =IF(OR($D2="",$E2=""),"",IF(AND($D2<=IF('Client & Project Profile'!$B$10="",TODAY(),'Client & Project Profile'!$B$10)+10*7+6,$E2>=IF('Client & Project Profile'!$B$10="",TODAY(),'Client & Project Profile'!$B$10)+10*7),"■","")) | X2: =IF(OR($D2="",$E2=""),"",IF(AND($D2<=IF('Client & Project Profile'!$B$10="",TODAY(),'Client & Project Profile'!$B$10)+11*7+6,$E2>=IF('Client & Project Profile'!$B$10="",TODAY(),'Client & Project Profile'!$B$10)+11*7),"■",""))
K3: =IF(OR($D3="",$E3=""),"",$E3-$D3+1) | L3: =IF(AND($E3<TODAY(),$G3<>"Complete"),TODAY()-$E3,0) | M3: =IF(OR($D3="",$E3=""),"",IF(AND($D3<=IF('Client & Project Profile'!$B$10="",TODAY(),'Client & Project Profile'!$B$10)+0*7+6,$E3>=IF('Client & Project Profile'!$B$10="",TODAY(),'Client & Project Profile'!$B$10)+0*7),"■","")) | N3: =IF(OR($D3="",$E3=""),"",IF(AND($D3<=IF('Client & Project Profile'!$B$10="",TODAY(),'Client & Project Profile'!$B$10)+1*7+6,$E3>=IF('Client & Project Profile'!$B$10="",TODAY(),'Client & Project Profile'!$B$10)+1*7),"■","")) | O3: =IF(OR($D3="",$E3=""),"",IF(AND($D3<=IF('Client & Project Profile'!$B$10="",TODAY(),'Client & Project Profile'!$B$10)+2*7+6,$E3>=IF('Client & Project Profile'!$B$10="",TODAY(),'Client & Project Profile'!$B$10)+2*7),"■","")) | P3: =IF(OR($D3="",$E3=""),"",IF(AND($D3<=IF('Client & Project Profile'!$B$10="",TODAY(),'Client & Project Profile'!$B$10)+3*7+6,$E3>=IF('Client & Project Profile'!$B$10="",TODAY(),'Client & Project Profile'!$B$10)+3*7),"■","")) | Q3: =IF(OR($D3="",$E3=""),"",IF(AND($D3<=IF('Client & Project Profile'!$B$10="",TODAY(),'Client & Project Profile'!$B$10)+4*7+6,$E3>=IF('Client & Project Profile'!$B$10="",TODAY(),'Client & Project Profile'!$B$10)+4*7),"■","")) | R3: =IF(OR($D3="",$E3=""),"",IF(AND($D3<=IF('Client & Project Profile'!$B$10="",TODAY(),'Client & Project Profile'!$B$10)+5*7+6,$E3>=IF('Client & Project Profile'!$B$10="",TODAY(),'Client & Project Profile'!$B$10)+5*7),"■","")) | S3: =IF(OR($D3="",$E3=""),"",IF(AND($D3<=IF('Client & Project Profile'!$B$10="",TODAY(),'Client & Project Profile'!$B$10)+6*7+6,$E3>=IF('Client & Project Profile'!$B$10="",TODAY(),'Client & Project Profile'!$B$10)+6*7),"■","")) | T3: =IF(OR($D3="",$E3=""),"",IF(AND($D3<=IF('Client & Project Profile'!$B$10="",TODAY(),'Client & Project Profile'!$B$10)+7*7+6,$E3>=IF('Client & Project Profile'!$B$10="",TODAY(),'Client & Project Profile'!$B$10)+7*7),"■","")) | U3: =IF(OR($D3="",$E3=""),"",IF(AND($D3<=IF('Client & Project Profile'!$B$10="",TODAY(),'Client & Project Profile'!$B$10)+8*7+6,$E3>=IF('Client & Project Profile'!$B$10="",TODAY(),'Client & Project Profile'!$B$10)+8*7),"■","")) | V3: =IF(OR($D3="",$E3=""),"",IF(AND($D3<=IF('Client & Project Profile'!$B$10="",TODAY(),'Client & Project Profile'!$B$10)+9*7+6,$E3>=IF('Client & Project Profile'!$B$10="",TODAY(),'Client & Project Profile'!$B$10)+9*7),"■","")) | W3: =IF(OR($D3="",$E3=""),"",IF(AND($D3<=IF('Client & Project Profile'!$B$10="",TODAY(),'Client & Project Profile'!$B$10)+10*7+6,$E3>=IF('Client & Project Profile'!$B$10="",TODAY(),'Client & Project Profile'!$B$10)+10*7),"■","")) | X3: =IF(OR($D3="",$E3=""),"",IF(AND($D3<=IF('Client & Project Profile'!$B$10="",TODAY(),'Client & Project Profile'!$B$10)+11*7+6,$E3>=IF('Client & Project Profile'!$B$10="",TODAY(),'Client & Project Profile'!$B$10)+11*7),"■",""))
K4: =IF(OR($D4="",$E4=""),"",$E4-$D4+1) | L4: =IF(AND($E4<TODAY(),$G4<>"Complete"),TODAY()-$E4,0) | M4: =IF(OR($D4="",$E4=""),"",IF(AND($D4<=IF('Client & Project Profile'!$B$10="",TODAY(),'Client & Project Profile'!$B$10)+0*7+6,$E4>=IF('Client & Project Profile'!$B$10="",TODAY(),'Client & Project Profile'!$B$10)+0*7),"■","")) | N4: =IF(OR($D4="",$E4=""),"",IF(AND($D4<=IF('Client & Project Profile'!$B$10="",TODAY(),'Client & Project Profile'!$B$10)+1*7+6,$E4>=IF('Client & Project Profile'!$B$10="",TODAY(),'Client & Project Profile'!$B$10)+1*7),"■","")) | O4: =IF(OR($D4="",$E4=""),"",IF(AND($D4<=IF('Client & Project Profile'!$B$10="",TODAY(),'Client & Project Profile'!$B$10)+2*7+6,$E4>=IF('Client & Project Profile'!$B$10="",TODAY(),'Client & Project Profile'!$B$10)+2*7),"■","")) | P4: =IF(OR($D4="",$E4=""),"",IF(AND($D4<=IF('Client & Project Profile'!$B$10="",TODAY(),'Client & Project Profile'!$B$10)+3*7+6,$E4>=IF('Client & Project Profile'!$B$10="",TODAY(),'Client & Project Profile'!$B$10)+3*7),"■","")) | Q4: =IF(OR($D4="",$E4=""),"",IF(AND($D4<=IF('Client & Project Profile'!$B$10="",TODAY(),'Client & Project Profile'!$B$10)+4*7+6,$E4>=IF('Client & Project Profile'!$B$10="",TODAY(),'Client & Project Profile'!$B$10)+4*7),"■","")) | R4: =IF(OR($D4="",$E4=""),"",IF(AND($D4<=IF('Client & Project Profile'!$B$10="",TODAY(),'Client & Project Profile'!$B$10)+5*7+6,$E4>=IF('Client & Project Profile'!$B$10="",TODAY(),'Client & Project Profile'!$B$10)+5*7),"■","")) | S4: =IF(OR($D4="",$E4=""),"",IF(AND($D4<=IF('Client & Project Profile'!$B$10="",TODAY(),'Client & Project Profile'!$B$10)+6*7+6,$E4>=IF('Client & Project Profile'!$B$10="",TODAY(),'Client & Project Profile'!$B$10)+6*7),"■","")) | T4: =IF(OR($D4="",$E4=""),"",IF(AND($D4<=IF('Client & Project Profile'!$B$10="",TODAY(),'Client & Project Profile'!$B$10)+7*7+6,$E4>=IF('Client & Project Profile'!$B$10="",TODAY(),'Client & Project Profile'!$B$10)+7*7),"■","")) | U4: =IF(OR($D4="",$E4=""),"",IF(AND($D4<=IF('Client & Project Profile'!$B$10="",TODAY(),'Client & Project Profile'!$B$10)+8*7+6,$E4>=IF('Client & Project Profile'!$B$10="",TODAY(),'Client & Project Profile'!$B$10)+8*7),"■","")) | V4: =IF(OR($D4="",$E4=""),"",IF(AND($D4<=IF('Client & Project Profile'!$B$10="",TODAY(),'Client & Project Profile'!$B$10)+9*7+6,$E4>=IF('Client & Project Profile'!$B$10="",TODAY(),'Client & Project Profile'!$B$10)+9*7),"■","")) | W4: =IF(OR($D4="",$E4=""),"",IF(AND($D4<=IF('Client & Project Profile'!$B$10="",TODAY(),'Client & Project Profile'!$B$10)+10*7+6,$E4>=IF('Client & Project Profile'!$B$10="",TODAY(),'Client & Project Profile'!$B$10)+10*7),"■","")) | X4: =IF(OR($D4="",$E4=""),"",IF(AND($D4<=IF('Client & Project Profile'!$B$10="",TODAY(),'Client & Project Profile'!$B$10)+11*7+6,$E4>=IF('Client & Project Profile'!$B$10="",TODAY(),'Client & Project Profile'!$B$10)+11*7),"■",""))
K5: =IF(OR($D5="",$E5=""),"",$E5-$D5+1) | L5: =IF(AND($E5<TODAY(),$G5<>"Complete"),TODAY()-$E5,0) | M5: =IF(OR($D5="",$E5=""),"",IF(AND($D5<=IF('Client & Project Profile'!$B$10="",TODAY(),'Client & Project Profile'!$B$10)+0*7+6,$E5>=IF('Client & Project Profile'!$B$10="",TODAY(),'Client & Project Profile'!$B$10)+0*7),"■","")) | N5: =IF(OR($D5="",$E5=""),"",IF(AND($D5<=IF('Client & Project Profile'!$B$10="",TODAY(),'Client & Project Profile'!$B$10)+1*7+6,$E5>=IF('Client & Project Profile'!$B$10="",TODAY(),'Client & Project Profile'!$B$10)+1*7),"■","")) | O5: =IF(OR($D5="",$E5=""),"",IF(AND($D5<=IF('Client & Project Profile'!$B$10="",TODAY(),'Client & Project Profile'!$B$10)+2*7+6,$E5>=IF('Client & Project Profile'!$B$10="",TODAY(),'Client & Project Profile'!$B$10)+2*7),"■","")) | P5: =IF(OR($D5="",$E5=""),"",IF(AND($D5<=IF('Client & Project Profile'!$B$10="",TODAY(),'Client & Project Profile'!$B$10)+3*7+6,$E5>=IF('Client & Project Profile'!$B$10="",TODAY(),'Client & Project Profile'!$B$10)+3*7),"■","")) | Q5: =IF(OR($D5="",$E5=""),"",IF(AND($D5<=IF('Client & Project Profile'!$B$10="",TODAY(),'Client & Project Profile'!$B$10)+4*7+6,$E5>=IF('Client & Project Profile'!$B$10="",TODAY(),'Client & Project Profile'!$B$10)+4*7),"■","")) | R5: =IF(OR($D5="",$E5=""),"",IF(AND($D5<=IF('Client & Project Profile'!$B$10="",TODAY(),'Client & Project Profile'!$B$10)+5*7+6,$E5>=IF('Client & Project Profile'!$B$10="",TODAY(),'Client & Project Profile'!$B$10)+5*7),"■","")) | S5: =IF(OR($D5="",$E5=""),"",IF(AND($D5<=IF('Client & Project Profile'!$B$10="",TODAY(),'Client & Project Profile'!$B$10)+6*7+6,$E5>=IF('Client & Project Profile'!$B$10="",TODAY(),'Client & Project Profile'!$B$10)+6*7),"■","")) | T5: =IF(OR($D5="",$E5=""),"",IF(AND($D5<=IF('Client & Project Profile'!$B$10="",TODAY(),'Client & Project Profile'!$B$10)+7*7+6,$E5>=IF('Client & Project Profile'!$B$10="",TODAY(),'Client & Project Profile'!$B$10)+7*7),"■","")) | U5: =IF(OR($D5="",$E5=""),"",IF(AND($D5<=IF('Client & Project Profile'!$B$10="",TODAY(),'Client & Project Profile'!$B$10)+8*7+6,$E5>=IF('Client & Project Profile'!$B$10="",TODAY(),'Client & Project Profile'!$B$10)+8*7),"■","")) | V5: =IF(OR($D5="",$E5=""),"",IF(AND($D5<=IF('Client & Project Profile'!$B$10="",TODAY(),'Client & Project Profile'!$B$10)+9*7+6,$E5>=IF('Client & Project Profile'!$B$10="",TODAY(),'Client & Project Profile'!$B$10)+9*7),"■","")) | W5: =IF(OR($D5="",$E5=""),"",IF(AND($D5<=IF('Client & Project Profile'!$B$10="",TODAY(),'Client & Project Profile'!$B$10)+10*7+6,$E5>=IF('Client & Project Profile'!$B$10="",TODAY(),'Client & Project Profile'!$B$10)+10*7),"■","")) | X5: =IF(OR($D5="",$E5=""),"",IF(AND($D5<=IF('Client & Project Profile'!$B$10="",TODAY(),'Client & Project Profile'!$B$10)+11*7+6,$E5>=IF('Client & Project Profile'!$B$10="",TODAY(),'Client & Project Profile'!$B$10)+11*7),"■",""))
K6: =IF(OR($D6="",$E6=""),"",$E6-$D6+1) | L6: =IF(AND($E6<TODAY(),$G6<>"Complete"),TODAY()-$E6,0) | M6: =IF(OR($D6="",$E6=""),"",IF(AND($D6<=IF('Client & Project Profile'!$B$10="",TODAY(),'Client & Project Profile'!$B$10)+0*7+6,$E6>=IF('Client & Project Profile'!$B$10="",TODAY(),'Client & Project Profile'!$B$10)+0*7),"■","")) | N6: =IF(OR($D6="",$E6=""),"",IF(AND($D6<=IF('Client & Project Profile'!$B$10="",TODAY(),'Client & Project Profile'!$B$10)+1*7+6,$E6>=IF('Client & Project Profile'!$B$10="",TODAY(),'Client & Project Profile'!$B$10)+1*7),"■","")) | O6: =IF(OR($D6="",$E6=""),"",IF(AND($D6<=IF('Client & Project Profile'!$B$10="",TODAY(),'Client & Project Profile'!$B$10)+2*7+6,$E6>=IF('Client & Project Profile'!$B$10="",TODAY(),'Client & Project Profile'!$B$10)+2*7),"■","")) | P6: =IF(OR($D6="",$E6=""),"",IF(AND($D6<=IF('Client & Project Profile'!$B$10="",TODAY(),'Client & Project Profile'!$B$10)+3*7+6,$E6>=IF('Client & Project Profile'!$B$10="",TODAY(),'Client & Project Profile'!$B$10)+3*7),"■","")) | Q6: =IF(OR($D6="",$E6=""),"",IF(AND($D6<=IF('Client & Project Profile'!$B$10="",TODAY(),'Client & Project Profile'!$B$10)+4*7+6,$E6>=IF('Client & Project Profile'!$B$10="",TODAY(),'Client & Project Profile'!$B$10)+4*7),"■","")) | R6: =IF(OR($D6="",$E6=""),"",IF(AND($D6<=IF('Client & Project Profile'!$B$10="",TODAY(),'Client & Project Profile'!$B$10)+5*7+6,$E6>=IF('Client & Project Profile'!$B$10="",TODAY(),'Client & Project Profile'!$B$10)+5*7),"■","")) | S6: =IF(OR($D6="",$E6=""),"",IF(AND($D6<=IF('Client & Project Profile'!$B$10="",TODAY(),'Client & Project Profile'!$B$10)+6*7+6,$E6>=IF('Client & Project Profile'!$B$10="",TODAY(),'Client & Project Profile'!$B$10)+6*7),"■","")) | T6: =IF(OR($D6="",$E6=""),"",IF(AND($D6<=IF('Client & Project Profile'!$B$10="",TODAY(),'Client & Project Profile'!$B$10)+7*7+6,$E6>=IF('Client & Project Profile'!$B$10="",TODAY(),'Client & Project Profile'!$B$10)+7*7),"■","")) | U6: =IF(OR($D6="",$E6=""),"",IF(AND($D6<=IF('Client & Project Profile'!$B$10="",TODAY(),'Client & Project Profile'!$B$10)+8*7+6,$E6>=IF('Client & Project Profile'!$B$10="",TODAY(),'Client & Project Profile'!$B$10)+8*7),"■","")) | V6: =IF(OR($D6="",$E6=""),"",IF(AND($D6<=IF('Client & Project Profile'!$B$10="",TODAY(),'Client & Project Profile'!$B$10)+9*7+6,$E6>=IF('Client & Project Profile'!$B$10="",TODAY(),'Client & Project Profile'!$B$10)+9*7),"■","")) | W6: =IF(OR($D6="",$E6=""),"",IF(AND($D6<=IF('Client & Project Profile'!$B$10="",TODAY(),'Client & Project Profile'!$B$10)+10*7+6,$E6>=IF('Client & Project Profile'!$B$10="",TODAY(),'Client & Project Profile'!$B$10)+10*7),"■","")) | X6: =IF(OR($D6="",$E6=""),"",IF(AND($D6<=IF('Client & Project Profile'!$B$10="",TODAY(),'Client & Project Profile'!$B$10)+11*7+6,$E6>=IF('Client & Project Profile'!$B$10="",TODAY(),'Client & Project Profile'!$B$10)+11*7),"■",""))
K7: =IF(OR($D7="",$E7=""),"",$E7-$D7+1) | L7: =IF(AND($E7<TODAY(),$G7<>"Complete"),TODAY()-$E7,0) | M7: =IF(OR($D7="",$E7=""),"",IF(AND($D7<=IF('Client & Project Profile'!$B$10="",TODAY(),'Client & Project Profile'!$B$10)+0*7+6,$E7>=IF('Client & Project Profile'!$B$10="",TODAY(),'Client & Project Profile'!$B$10)+0*7),"■","")) | N7: =IF(OR($D7="",$E7=""),"",IF(AND($D7<=IF('Client & Project Profile'!$B$10="",TODAY(),'Client & Project Profile'!$B$10)+1*7+6,$E7>=IF('Client & Project Profile'!$B$10="",TODAY(),'Client & Project Profile'!$B$10)+1*7),"■","")) | O7: =IF(OR($D7="",$E7=""),"",IF(AND($D7<=IF('Client & Project Profile'!$B$10="",TODAY(),'Client & Project Profile'!$B$10)+2*7+6,$E7>=IF('Client & Project Profile'!$B$10="",TODAY(),'Client & Project Profile'!$B$10)+2*7),"■","")) | P7: =IF(OR($D7="",$E7=""),"",IF(AND($D7<=IF('Client & Project Profile'!$B$10="",TODAY(),'Client & Project Profile'!$B$10)+3*7+6,$E7>=IF('Client & Project Profile'!$B$10="",TODAY(),'Client & Project Profile'!$B$10)+3*7),"■","")) | Q7: =IF(OR($D7="",$E7=""),"",IF(AND($D7<=IF('Client & Project Profile'!$B$10="",TODAY(),'Client & Project Profile'!$B$10)+4*7+6,$E7>=IF('Client & Project Profile'!$B$10="",TODAY(),'Client & Project Profile'!$B$10)+4*7),"■","")) | R7: =IF(OR($D7="",$E7=""),"",IF(AND($D7<=IF('Client & Project Profile'!$B$10="",TODAY(),'Client & Project Profile'!$B$10)+5*7+6,$E7>=IF('Client & Project Profile'!$B$10="",TODAY(),'Client & Project Profile'!$B$10)+5*7),"■","")) | S7: =IF(OR($D7="",$E7=""),"",IF(AND($D7<=IF('Client & Project Profile'!$B$10="",TODAY(),'Client & Project Profile'!$B$10)+6*7+6,$E7>=IF('Client & Project Profile'!$B$10="",TODAY(),'Client & Project Profile'!$B$10)+6*7),"■","")) | T7: =IF(OR($D7="",$E7=""),"",IF(AND($D7<=IF('Client & Project Profile'!$B$10="",TODAY(),'Client & Project Profile'!$B$10)+7*7+6,$E7>=IF('Client & Project Profile'!$B$10="",TODAY(),'Client & Project Profile'!$B$10)+7*7),"■","")) | U7: =IF(OR($D7="",$E7=""),"",IF(AND($D7<=IF('Client & Project Profile'!$B$10="",TODAY(),'Client & Project Profile'!$B$10)+8*7+6,$E7>=IF('Client & Project Profile'!$B$10="",TODAY(),'Client & Project Profile'!$B$10)+8*7),"■","")) | V7: =IF(OR($D7="",$E7=""),"",IF(AND($D7<=IF('Client & Project Profile'!$B$10="",TODAY(),'Client & Project Profile'!$B$10)+9*7+6,$E7>=IF('Client & Project Profile'!$B$10="",TODAY(),'Client & Project Profile'!$B$10)+9*7),"■","")) | W7: =IF(OR($D7="",$E7=""),"",IF(AND($D7<=IF('Client & Project Profile'!$B$10="",TODAY(),'Client & Project Profile'!$B$10)+10*7+6,$E7>=IF('Client & Project Profile'!$B$10="",TODAY(),'Client & Project Profile'!$B$10)+10*7),"■","")) | X7: =IF(OR($D7="",$E7=""),"",IF(AND($D7<=IF('Client & Project Profile'!$B$10="",TODAY(),'Client & Project Profile'!$B$10)+11*7+6,$E7>=IF('Client & Project Profile'!$B$10="",TODAY(),'Client & Project Profile'!$B$10)+11*7),"■",""))
K8: =IF(OR($D8="",$E8=""),"",$E8-$D8+1) | L8: =IF(AND($E8<TODAY(),$G8<>"Complete"),TODAY()-$E8,0) | M8: =IF(OR($D8="",$E8=""),"",IF(AND($D8<=IF('Client & Project Profile'!$B$10="",TODAY(),'Client & Project Profile'!$B$10)+0*7+6,$E8>=IF('Client & Project Profile'!$B$10="",TODAY(),'Client & Project Profile'!$B$10)+0*7),"■","")) | N8: =IF(OR($D8="",$E8=""),"",IF(AND($D8<=IF('Client & Project Profile'!$B$10="",TODAY(),'Client & Project Profile'!$B$10)+1*7+6,$E8>=IF('Client & Project Profile'!$B$10="",TODAY(),'Client & Project Profile'!$B$10)+1*7),"■","")) | O8: =IF(OR($D8="",$E8=""),"",IF(AND($D8<=IF('Client & Project Profile'!$B$10="",TODAY(),'Client & Project Profile'!$B$10)+2*7+6,$E8>=IF('Client & Project Profile'!$B$10="",TODAY(),'Client & Project Profile'!$B$10)+2*7),"■","")) | P8: =IF(OR($D8="",$E8=""),"",IF(AND($D8<=IF('Client & Project Profile'!$B$10="",TODAY(),'Client & Project Profile'!$B$10)+3*7+6,$E8>=IF('Client & Project Profile'!$B$10="",TODAY(),'Client & Project Profile'!$B$10)+3*7),"■","")) | Q8: =IF(OR($D8="",$E8=""),"",IF(AND($D8<=IF('Client & Project Profile'!$B$10="",TODAY(),'Client & Project Profile'!$B$10)+4*7+6,$E8>=IF('Client & Project Profile'!$B$10="",TODAY(),'Client & Project Profile'!$B$10)+4*7),"■","")) | R8: =IF(OR($D8="",$E8=""),"",IF(AND($D8<=IF('Client & Project Profile'!$B$10="",TODAY(),'Client & Project Profile'!$B$10)+5*7+6,$E8>=IF('Client & Project Profile'!$B$10="",TODAY(),'Client & Project Profile'!$B$10)+5*7),"■","")) | S8: =IF(OR($D8="",$E8=""),"",IF(AND($D8<=IF('Client & Project Profile'!$B$10="",TODAY(),'Client & Project Profile'!$B$10)+6*7+6,$E8>=IF('Client & Project Profile'!$B$10="",TODAY(),'Client & Project Profile'!$B$10)+6*7),"■","")) | T8: =IF(OR($D8="",$E8=""),"",IF(AND($D8<=IF('Client & Project Profile'!$B$10="",TODAY(),'Client & Project Profile'!$B$10)+7*7+6,$E8>=IF('Client & Project Profile'!$B$10="",TODAY(),'Client & Project Profile'!$B$10)+7*7),"■","")) | U8: =IF(OR($D8="",$E8=""),"",IF(AND($D8<=IF('Client & Project Profile'!$B$10="",TODAY(),'Client & Project Profile'!$B$10)+8*7+6,$E8>=IF('Client & Project Profile'!$B$10="",TODAY(),'Client & Project Profile'!$B$10)+8*7),"■","")) | V8: =IF(OR($D8="",$E8=""),"",IF(AND($D8<=IF('Client & Project Profile'!$B$10="",TODAY(),'Client & Project Profile'!$B$10)+9*7+6,$E8>=IF('Client & Project Profile'!$B$10="",TODAY(),'Client & Project Profile'!$B$10)+9*7),"■","")) | W8: =IF(OR($D8="",$E8=""),"",IF(AND($D8<=IF('Client & Project Profile'!$B$10="",TODAY(),'Client & Project Profile'!$B$10)+10*7+6,$E8>=IF('Client & Project Profile'!$B$10="",TODAY(),'Client & Project Profile'!$B$10)+10*7),"■","")) | X8: =IF(OR($D8="",$E8=""),"",IF(AND($D8<=IF('Client & Project Profile'!$B$10="",TODAY(),'Client & Project Profile'!$B$10)+11*7+6,$E8>=IF('Client & Project Profile'!$B$10="",TODAY(),'Client & Project Profile'!$B$10)+11*7),"■",""))
K9: =IF(OR($D9="",$E9=""),"",$E9-$D9+1) | L9: =IF(AND($E9<TODAY(),$G9<>"Complete"),TODAY()-$E9,0) | M9: =IF(OR($D9="",$E9=""),"",IF(AND($D9<=IF('Client & Project Profile'!$B$10="",TODAY(),'Client & Project Profile'!$B$10)+0*7+6,$E9>=IF('Client & Project Profile'!$B$10="",TODAY(),'Client & Project Profile'!$B$10)+0*7),"■","")) | N9: =IF(OR($D9="",$E9=""),"",IF(AND($D9<=IF('Client & Project Profile'!$B$10="",TODAY(),'Client & Project Profile'!$B$10)+1*7+6,$E9>=IF('Client & Project Profile'!$B$10="",TODAY(),'Client & Project Profile'!$B$10)+1*7),"■","")) | O9: =IF(OR($D9="",$E9=""),"",IF(AND($D9<=IF('Client & Project Profile'!$B$10="",TODAY(),'Client & Project Profile'!$B$10)+2*7+6,$E9>=IF('Client & Project Profile'!$B$10="",TODAY(),'Client & Project Profile'!$B$10)+2*7),"■","")) | P9: =IF(OR($D9="",$E9=""),"",IF(AND($D9<=IF('Client & Project Profile'!$B$10="",TODAY(),'Client & Project Profile'!$B$10)+3*7+6,$E9>=IF('Client & Project Profile'!$B$10="",TODAY(),'Client & Project Profile'!$B$10)+3*7),"■","")) | Q9: =IF(OR($D9="",$E9=""),"",IF(AND($D9<=IF('Client & Project Profile'!$B$10="",TODAY(),'Client & Project Profile'!$B$10)+4*7+6,$E9>=IF('Client & Project Profile'!$B$10="",TODAY(),'Client & Project Profile'!$B$10)+4*7),"■","")) | R9: =IF(OR($D9="",$E9=""),"",IF(AND($D9<=IF('Client & Project Profile'!$B$10="",TODAY(),'Client & Project Profile'!$B$10)+5*7+6,$E9>=IF('Client & Project Profile'!$B$10="",TODAY(),'Client & Project Profile'!$B$10)+5*7),"■","")) | S9: =IF(OR($D9="",$E9=""),"",IF(AND($D9<=IF('Client & Project Profile'!$B$10="",TODAY(),'Client & Project Profile'!$B$10)+6*7+6,$E9>=IF('Client & Project Profile'!$B$10="",TODAY(),'Client & Project Profile'!$B$10)+6*7),"■","")) | T9: =IF(OR($D9="",$E9=""),"",IF(AND($D9<=IF('Client & Project Profile'!$B$10="",TODAY(),'Client & Project Profile'!$B$10)+7*7+6,$E9>=IF('Client & Project Profile'!$B$10="",TODAY(),'Client & Project Profile'!$B$10)+7*7),"■","")) | U9: =IF(OR($D9="",$E9=""),"",IF(AND($D9<=IF('Client & Project Profile'!$B$10="",TODAY(),'Client & Project Profile'!$B$10)+8*7+6,$E9>=IF('Client & Project Profile'!$B$10="",TODAY(),'Client & Project Profile'!$B$10)+8*7),"■","")) | V9: =IF(OR($D9="",$E9=""),"",IF(AND($D9<=IF('Client & Project Profile'!$B$10="",TODAY(),'Client & Project Profile'!$B$10)+9*7+6,$E9>=IF('Client & Project Profile'!$B$10="",TODAY(),'Client & Project Profile'!$B$10)+9*7),"■","")) | W9: =IF(OR($D9="",$E9=""),"",IF(AND($D9<=IF('Client & Project Profile'!$B$10="",TODAY(),'Client & Project Profile'!$B$10)+10*7+6,$E9>=IF('Client & Project Profile'!$B$10="",TODAY(),'Client & Project Profile'!$B$10)+10*7),"■","")) | X9: =IF(OR($D9="",$E9=""),"",IF(AND($D9<=IF('Client & Project Profile'!$B$10="",TODAY(),'Client & Project Profile'!$B$10)+11*7+6,$E9>=IF('Client & Project Profile'!$B$10="",TODAY(),'Client & Project Profile'!$B$10)+11*7),"■",""))
K10: =IF(OR($D10="",$E10=""),"",$E10-$D10+1) | L10: =IF(AND($E10<TODAY(),$G10<>"Complete"),TODAY()-$E10,0) | M10: =IF(OR($D10="",$E10=""),"",IF(AND($D10<=IF('Client & Project Profile'!$B$10="",TODAY(),'Client & Project Profile'!$B$10)+0*7+6,$E10>=IF('Client & Project Profile'!$B$10="",TODAY(),'Client & Project Profile'!$B$10)+0*7),"■","")) | N10: =IF(OR($D10="",$E10=""),"",IF(AND($D10<=IF('Client & Project Profile'!$B$10="",TODAY(),'Client & Project Profile'!$B$10)+1*7+6,$E10>=IF('Client & Project Profile'!$B$10="",TODAY(),'Client & Project Profile'!$B$10)+1*7),"■","")) | O10: =IF(OR($D10="",$E10=""),"",IF(AND($D10<=IF('Client & Project Profile'!$B$10="",TODAY(),'Client & Project Profile'!$B$10)+2*7+6,$E10>=IF('Client & Project Profile'!$B$10="",TODAY(),'Client & Project Profile'!$B$10)+2*7),"■","")) | P10: =IF(OR($D10="",$E10=""),"",IF(AND($D10<=IF('Client & Project Profile'!$B$10="",TODAY(),'Client & Project Profile'!$B$10)+3*7+6,$E10>=IF('Client & Project Profile'!$B$10="",TODAY(),'Client & Project Profile'!$B$10)+3*7),"■","")) | Q10: =IF(OR($D10="",$E10=""),"",IF(AND($D10<=IF('Client & Project Profile'!$B$10="",TODAY(),'Client & Project Profile'!$B$10)+4*7+6,$E10>=IF('Client & Project Profile'!$B$10="",TODAY(),'Client & Project Profile'!$B$10)+4*7),"■","")) | R10: =IF(OR($D10="",$E10=""),"",IF(AND($D10<=IF('Client & Project Profile'!$B$10="",TODAY(),'Client & Project Profile'!$B$10)+5*7+6,$E10>=IF('Client & Project Profile'!$B$10="",TODAY(),'Client & Project Profile'!$B$10)+5*7),"■","")) | S10: =IF(OR($D10="",$E10=""),"",IF(AND($D10<=IF('Client & Project Profile'!$B$10="",TODAY(),'Client & Project Profile'!$B$10)+6*7+6,$E10>=IF('Client & Project Profile'!$B$10="",TODAY(),'Client & Project Profile'!$B$10)+6*7),"■","")) | T10: =IF(OR($D10="",$E10=""),"",IF(AND($D10<=IF('Client & Project Profile'!$B$10="",TODAY(),'Client & Project Profile'!$B$10)+7*7+6,$E10>=IF('Client & Project Profile'!$B$10="",TODAY(),'Client & Project Profile'!$B$10)+7*7),"■","")) | U10: =IF(OR($D10="",$E10=""),"",IF(AND($D10<=IF('Client & Project Profile'!$B$10="",TODAY(),'Client & Project Profile'!$B$10)+8*7+6,$E10>=IF('Client & Project Profile'!$B$10="",TODAY(),'Client & Project Profile'!$B$10)+8*7),"■","")) | V10: =IF(OR($D10="",$E10=""),"",IF(AND($D10<=IF('Client & Project Profile'!$B$10="",TODAY(),'Client & Project Profile'!$B$10)+9*7+6,$E10>=IF('Client & Project Profile'!$B$10="",TODAY(),'Client & Project Profile'!$B$10)+9*7),"■","")) | W10: =IF(OR($D10="",$E10=""),"",IF(AND($D10<=IF('Client & Project Profile'!$B$10="",TODAY(),'Client & Project Profile'!$B$10)+10*7+6,$E10>=IF('Client & Project Profile'!$B$10="",TODAY(),'Client & Project Profile'!$B$10)+10*7),"■","")) | X10: =IF(OR($D10="",$E10=""),"",IF(AND($D10<=IF('Client & Project Profile'!$B$10="",TODAY(),'Client & Project Profile'!$B$10)+11*7+6,$E10>=IF('Client & Project Profile'!$B$10="",TODAY(),'Client & Project Profile'!$B$10)+11*7),"■",""))
K11: =IF(OR($D11="",$E11=""),"",$E11-$D11+1) | L11: =IF(AND($E11<TODAY(),$G11<>"Complete"),TODAY()-$E11,0) | M11: =IF(OR($D11="",$E11=""),"",IF(AND($D11<=IF('Client & Project Profile'!$B$10="",TODAY(),'Client & Project Profile'!$B$10)+0*7+6,$E11>=IF('Client & Project Profile'!$B$10="",TODAY(),'Client & Project Profile'!$B$10)+0*7),"■","")) | N11: =IF(OR($D11="",$E11=""),"",IF(AND($D11<=IF('Client & Project Profile'!$B$10="",TODAY(),'Client & Project Profile'!$B$10)+1*7+6,$E11>=IF('Client & Project Profile'!$B$10="",TODAY(),'Client & Project Profile'!$B$10)+1*7),"■","")) | O11: =IF(OR($D11="",$E11=""),"",IF(AND($D11<=IF('Client & Project Profile'!$B$10="",TODAY(),'Client & Project Profile'!$B$10)+2*7+6,$E11>=IF('Client & Project Profile'!$B$10="",TODAY(),'Client & Project Profile'!$B$10)+2*7),"■","")) | P11: =IF(OR($D11="",$E11=""),"",IF(AND($D11<=IF('Client & Project Profile'!$B$10="",TODAY(),'Client & Project Profile'!$B$10)+3*7+6,$E11>=IF('Client & Project Profile'!$B$10="",TODAY(),'Client & Project Profile'!$B$10)+3*7),"■","")) | Q11: =IF(OR($D11="",$E11=""),"",IF(AND($D11<=IF('Client & Project Profile'!$B$10="",TODAY(),'Client & Project Profile'!$B$10)+4*7+6,$E11>=IF('Client & Project Profile'!$B$10="",TODAY(),'Client & Project Profile'!$B$10)+4*7),"■","")) | R11: =IF(OR($D11="",$E11=""),"",IF(AND($D11<=IF('Client & Project Profile'!$B$10="",TODAY(),'Client & Project Profile'!$B$10)+5*7+6,$E11>=IF('Client & Project Profile'!$B$10="",TODAY(),'Client & Project Profile'!$B$10)+5*7),"■","")) | S11: =IF(OR($D11="",$E11=""),"",IF(AND($D11<=IF('Client & Project Profile'!$B$10="",TODAY(),'Client & Project Profile'!$B$10)+6*7+6,$E11>=IF('Client & Project Profile'!$B$10="",TODAY(),'Client & Project Profile'!$B$10)+6*7),"■","")) | T11: =IF(OR($D11="",$E11=""),"",IF(AND($D11<=IF('Client & Project Profile'!$B$10="",TODAY(),'Client & Project Profile'!$B$10)+7*7+6,$E11>=IF('Client & Project Profile'!$B$10="",TODAY(),'Client & Project Profile'!$B$10)+7*7),"■","")) | U11: =IF(OR($D11="",$E11=""),"",IF(AND($D11<=IF('Client & Project Profile'!$B$10="",TODAY(),'Client & Project Profile'!$B$10)+8*7+6,$E11>=IF('Client & Project Profile'!$B$10="",TODAY(),'Client & Project Profile'!$B$10)+8*7),"■","")) | V11: =IF(OR($D11="",$E11=""),"",IF(AND($D11<=IF('Client & Project Profile'!$B$10="",TODAY(),'Client & Project Profile'!$B$10)+9*7+6,$E11>=IF('Client & Project Profile'!$B$10="",TODAY(),'Client & Project Profile'!$B$10)+9*7),"■","")) | W11: =IF(OR($D11="",$E11=""),"",IF(AND($D11<=IF('Client & Project Profile'!$B$10="",TODAY(),'Client & Project Profile'!$B$10)+10*7+6,$E11>=IF('Client & Project Profile'!$B$10="",TODAY(),'Client & Project Profile'!$B$10)+10*7),"■","")) | X11: =IF(OR($D11="",$E11=""),"",IF(AND($D11<=IF('Client & Project Profile'!$B$10="",TODAY(),'Client & Project Profile'!$B$10)+11*7+6,$E11>=IF('Client & Project Profile'!$B$10="",TODAY(),'Client & Project Profile'!$B$10)+11*7),"■",""))
K12: =IF(OR($D12="",$E12=""),"",$E12-$D12+1) | L12: =IF(AND($E12<TODAY(),$G12<>"Complete"),TODAY()-$E12,0) | M12: =IF(OR($D12="",$E12=""),"",IF(AND($D12<=IF('Client & Project Profile'!$B$10="",TODAY(),'Client & Project Profile'!$B$10)+0*7+6,$E12>=IF('Client & Project Profile'!$B$10="",TODAY(),'Client & Project Profile'!$B$10)+0*7),"■","")) | N12: =IF(OR($D12="",$E12=""),"",IF(AND($D12<=IF('Client & Project Profile'!$B$10="",TODAY(),'Client & Project Profile'!$B$10)+1*7+6,$E12>=IF('Client & Project Profile'!$B$10="",TODAY(),'Client & Project Profile'!$B$10)+1*7),"■","")) | O12: =IF(OR($D12="",$E12=""),"",IF(AND($D12<=IF('Client & Project Profile'!$B$10="",TODAY(),'Client & Project Profile'!$B$10)+2*7+6,$E12>=IF('Client & Project Profile'!$B$10="",TODAY(),'Client & Project Profile'!$B$10)+2*7),"■","")) | P12: =IF(OR($D12="",$E12=""),"",IF(AND($D12<=IF('Client & Project Profile'!$B$10="",TODAY(),'Client & Project Profile'!$B$10)+3*7+6,$E12>=IF('Client & Project Profile'!$B$10="",TODAY(),'Client & Project Profile'!$B$10)+3*7),"■","")) | Q12: =IF(OR($D12="",$E12=""),"",IF(AND($D12<=IF('Client & Project Profile'!$B$10="",TODAY(),'Client & Project Profile'!$B$10)+4*7+6,$E12>=IF('Client & Project Profile'!$B$10="",TODAY(),'Client & Project Profile'!$B$10)+4*7),"■","")) | R12: =IF(OR($D12="",$E12=""),"",IF(AND($D12<=IF('Client & Project Profile'!$B$10="",TODAY(),'Client & Project Profile'!$B$10)+5*7+6,$E12>=IF('Client & Project Profile'!$B$10="",TODAY(),'Client & Project Profile'!$B$10)+5*7),"■","")) | S12: =IF(OR($D12="",$E12=""),"",IF(AND($D12<=IF('Client & Project Profile'!$B$10="",TODAY(),'Client & Project Profile'!$B$10)+6*7+6,$E12>=IF('Client & Project Profile'!$B$10="",TODAY(),'Client & Project Profile'!$B$10)+6*7),"■","")) | T12: =IF(OR($D12="",$E12=""),"",IF(AND($D12<=IF('Client & Project Profile'!$B$10="",TODAY(),'Client & Project Profile'!$B$10)+7*7+6,$E12>=IF('Client & Project Profile'!$B$10="",TODAY(),'Client & Project Profile'!$B$10)+7*7),"■","")) | U12: =IF(OR($D12="",$E12=""),"",IF(AND($D12<=IF('Client & Project Profile'!$B$10="",TODAY(),'Client & Project Profile'!$B$10)+8*7+6,$E12>=IF('Client & Project Profile'!$B$10="",TODAY(),'Client & Project Profile'!$B$10)+8*7),"■","")) | V12: =IF(OR($D12="",$E12=""),"",IF(AND($D12<=IF('Client & Project Profile'!$B$10="",TODAY(),'Client & Project Profile'!$B$10)+9*7+6,$E12>=IF('Client & Project Profile'!$B$10="",TODAY(),'Client & Project Profile'!$B$10)+9*7),"■","")) | W12: =IF(OR($D12="",$E12=""),"",IF(AND($D12<=IF('Client & Project Profile'!$B$10="",TODAY(),'Client & Project Profile'!$B$10)+10*7+6,$E12>=IF('Client & Project Profile'!$B$10="",TODAY(),'Client & Project Profile'!$B$10)+10*7),"■","")) | X12: =IF(OR($D12="",$E12=""),"",IF(AND($D12<=IF('Client & Project Profile'!$B$10="",TODAY(),'Client & Project Profile'!$B$10)+11*7+6,$E12>=IF('Client & Project Profile'!$B$10="",TODAY(),'Client & Project Profile'!$B$10)+11*7),"■",""))
K13: =IF(OR($D13="",$E13=""),"",$E13-$D13+1) | L13: =IF(AND($E13<TODAY(),$G13<>"Complete"),TODAY()-$E13,0) | M13: =IF(OR($D13="",$E13=""),"",IF(AND($D13<=IF('Client & Project Profile'!$B$10="",TODAY(),'Client & Project Profile'!$B$10)+0*7+6,$E13>=IF('Client & Project Profile'!$B$10="",TODAY(),'Client & Project Profile'!$B$10)+0*7),"■","")) | N13: =IF(OR($D13="",$E13=""),"",IF(AND($D13<=IF('Client & Project Profile'!$B$10="",TODAY(),'Client & Project Profile'!$B$10)+1*7+6,$E13>=IF('Client & Project Profile'!$B$10="",TODAY(),'Client & Project Profile'!$B$10)+1*7),"■","")) | O13: =IF(OR($D13="",$E13=""),"",IF(AND($D13<=IF('Client & Project Profile'!$B$10="",TODAY(),'Client & Project Profile'!$B$10)+2*7+6,$E13>=IF('Client & Project Profile'!$B$10="",TODAY(),'Client & Project Profile'!$B$10)+2*7),"■","")) | P13: =IF(OR($D13="",$E13=""),"",IF(AND($D13<=IF('Client & Project Profile'!$B$10="",TODAY(),'Client & Project Profile'!$B$10)+3*7+6,$E13>=IF('Client & Project Profile'!$B$10="",TODAY(),'Client & Project Profile'!$B$10)+3*7),"■","")) | Q13: =IF(OR($D13="",$E13=""),"",IF(AND($D13<=IF('Client & Project Profile'!$B$10="",TODAY(),'Client & Project Profile'!$B$10)+4*7+6,$E13>=IF('Client & Project Profile'!$B$10="",TODAY(),'Client & Project Profile'!$B$10)+4*7),"■","")) | R13: =IF(OR($D13="",$E13=""),"",IF(AND($D13<=IF('Client & Project Profile'!$B$10="",TODAY(),'Client & Project Profile'!$B$10)+5*7+6,$E13>=IF('Client & Project Profile'!$B$10="",TODAY(),'Client & Project Profile'!$B$10)+5*7),"■","")) | S13: =IF(OR($D13="",$E13=""),"",IF(AND($D13<=IF('Client & Project Profile'!$B$10="",TODAY(),'Client & Project Profile'!$B$10)+6*7+6,$E13>=IF('Client & Project Profile'!$B$10="",TODAY(),'Client & Project Profile'!$B$10)+6*7),"■","")) | T13: =IF(OR($D13="",$E13=""),"",IF(AND($D13<=IF('Client & Project Profile'!$B$10="",TODAY(),'Client & Project Profile'!$B$10)+7*7+6,$E13>=IF('Client & Project Profile'!$B$10="",TODAY(),'Client & Project Profile'!$B$10)+7*7),"■","")) | U13: =IF(OR($D13="",$E13=""),"",IF(AND($D13<=IF('Client & Project Profile'!$B$10="",TODAY(),'Client & Project Profile'!$B$10)+8*7+6,$E13>=IF('Client & Project Profile'!$B$10="",TODAY(),'Client & Project Profile'!$B$10)+8*7),"■","")) | V13: =IF(OR($D13="",$E13=""),"",IF(AND($D13<=IF('Client & Project Profile'!$B$10="",TODAY(),'Client & Project Profile'!$B$10)+9*7+6,$E13>=IF('Client & Project Profile'!$B$10="",TODAY(),'Client & Project Profile'!$B$10)+9*7),"■","")) | W13: =IF(OR($D13="",$E13=""),"",IF(AND($D13<=IF('Client & Project Profile'!$B$10="",TODAY(),'Client & Project Profile'!$B$10)+10*7+6,$E13>=IF('Client & Project Profile'!$B$10="",TODAY(),'Client & Project Profile'!$B$10)+10*7),"■","")) | X13: =IF(OR($D13="",$E13=""),"",IF(AND($D13<=IF('Client & Project Profile'!$B$10="",TODAY(),'Client & Project Profile'!$B$10)+11*7+6,$E13>=IF('Client & Project Profile'!$B$10="",TODAY(),'Client & Project Profile'!$B$10)+11*7),"■",""))
... K251: =IF(OR($D251="",$E251=""),"",$E251-$D251+1) | L251: =IF(AND($E251<TODAY(),$G251<>"Complete"),TODAY()-$E251,0) | M251: =IF(OR($D251="",$E251=""),"",IF(AND($D251<=IF('Client & Project Profile'!$B$10="",TODAY(),'Client & Project Profile'!$B$10)+0*7+6,$E251>=IF('Client & Project Profile'!$B$10="",TODAY(),'Client & Project Profile'!$B$10)+0*7),"■","")) | N251: =IF(OR($D251="",$E251=""),"",IF(AND($D251<=IF('Client & Project Profile'!$B$10="",TODAY(),'Client & Project Profile'!$B$10)+1*7+6,$E251>=IF('Client & Project Profile'!$B$10="",TODAY(),'Client & Project Profile'!$B$10)+1*7),"■","")) | O251: =IF(OR($D251="",$E251=""),"",IF(AND($D251<=IF('Client & Project Profile'!$B$10="",TODAY(),'Client & Project Profile'!$B$10)+2*7+6,$E251>=IF('Client & Project Profile'!$B$10="",TODAY(),'Client & Project Profile'!$B$10)+2*7),"■","")) | P251: =IF(OR($D251="",$E251=""),"",IF(AND($D251<=IF('Client & Project Profile'!$B$10="",TODAY(),'Client & Project Profile'!$B$10)+3*7+6,$E251>=IF('Client & Project Profile'!$B$10="",TODAY(),'Client & Project Profile'!$B$10)+3*7),"■","")) | Q251: =IF(OR($D251="",$E251=""),"",IF(AND($D251<=IF('Client & Project Profile'!$B$10="",TODAY(),'Client & Project Profile'!$B$10)+4*7+6,$E251>=IF('Client & Project Profile'!$B$10="",TODAY(),'Client & Project Profile'!$B$10)+4*7),"■","")) | R251: =IF(OR($D251="",$E251=""),"",IF(AND($D251<=IF('Client & Project Profile'!$B$10="",TODAY(),'Client & Project Profile'!$B$10)+5*7+6,$E251>=IF('Client & Project Profile'!$B$10="",TODAY(),'Client & Project Profile'!$B$10)+5*7),"■","")) | S251: =IF(OR($D251="",$E251=""),"",IF(AND($D251<=IF('Client & Project Profile'!$B$10="",TODAY(),'Client & Project Profile'!$B$10)+6*7+6,$E251>=IF('Client & Project Profile'!$B$10="",TODAY(),'Client & Project Profile'!$B$10)+6*7),"■","")) | T251: =IF(OR($D251="",$E251=""),"",IF(AND($D251<=IF('Client & Project Profile'!$B$10="",TODAY(),'Client & Project Profile'!$B$10)+7*7+6,$E251>=IF('Client & Project Profile'!$B$10="",TODAY(),'Client & Project Profile'!$B$10)+7*7),"■","")) | U251: =IF(OR($D251="",$E251=""),"",IF(AND($D251<=IF('Client & Project Profile'!$B$10="",TODAY(),'Client & Project Profile'!$B$10)+8*7+6,$E251>=IF('Client & Project Profile'!$B$10="",TODAY(),'Client & Project Profile'!$B$10)+8*7),"■","")) | V251: =IF(OR($D251="",$E251=""),"",IF(AND($D251<=IF('Client & Project Profile'!$B$10="",TODAY(),'Client & Project Profile'!$B$10)+9*7+6,$E251>=IF('Client & Project Profile'!$B$10="",TODAY(),'Client & Project Profile'!$B$10)+9*7),"■","")) | W251: =IF(OR($D251="",$E251=""),"",IF(AND($D251<=IF('Client & Project Profile'!$B$10="",TODAY(),'Client & Project Profile'!$B$10)+10*7+6,$E251>=IF('Client & Project Profile'!$B$10="",TODAY(),'Client & Project Profile'!$B$10)+10*7),"■","")) | X251: =IF(OR($D251="",$E251=""),"",IF(AND($D251<=IF('Client & Project Profile'!$B$10="",TODAY(),'Client & Project Profile'!$B$10)+11*7+6,$E251>=IF('Client & Project Profile'!$B$10="",TODAY(),'Client & Project Profile'!$B$10)+11*7),"■",""))

Sheet Task & To-Do List
A1: Task | B1: Room | C1: Category | D1: Assigned to | E1: Priority | F1: Due date | G1: Status | H1: Notes | I1: Days overdue
I2: =IF(AND($F2<TODAY(),$G2<>"Complete"),TODAY()-$F2,0)
I3: =IF(AND($F3<TODAY(),$G3<>"Complete"),TODAY()-$F3,0)
I4: =IF(AND($F4<TODAY(),$G4<>"Complete"),TODAY()-$F4,0)
I5: =IF(AND($F5<TODAY(),$G5<>"Complete"),TODAY()-$F5,0)
I6: =IF(AND($F6<TODAY(),$G6<>"Complete"),TODAY()-$F6,0)
I7: =IF(AND($F7<TODAY(),$G7<>"Complete"),TODAY()-$F7,0)
I8: =IF(AND($F8<TODAY(),$G8<>"Complete"),TODAY()-$F8,0)
I9: =IF(AND($F9<TODAY(),$G9<>"Complete"),TODAY()-$F9,0)
I10: =IF(AND($F10<TODAY(),$G10<>"Complete"),TODAY()-$F10,0)
I11: =IF(AND($F11<TODAY(),$G11<>"Complete"),TODAY()-$F11,0)
I12: =IF(AND($F12<TODAY(),$G12<>"Complete"),TODAY()-$F12,0)
I13: =IF(AND($F13<TODAY(),$G13<>"Complete"),TODAY()-$F13,0)
... I251: =IF(AND($F251<TODAY(),$G251<>"Complete"),TODAY()-$F251,0)

Sheet Measurement Log
A1: Room | B1: Measurement type | C1: Width | D1: Height | E1: Depth | F1: Length | G1: Ceiling height | H1: Window size | I1: Door size | J1: Wall length | K1: Notes

Sheet Contractor Installer Tracker
A1: Contractor/vendor name | B1: Trade | C1: Contact | D1: Scope | E1: Quote amount | F1: Start date | G1: End date | H1: Payment status | I1: Insurance received | J1: Contract signed | K1: Notes

Sheet Invoice Payment Tracker
A1: Invoice number | B1: Invoice date | C1: Client | D1: Description | E1: Amount | F1: Due date | G1: Paid date | H1: Payment status | I1: Payment method | J1: Notes | K1: Balance due
K2: =IF($A2="","",IF($H2="Paid",0,$E2))
K3: =IF($A3="","",IF($H3="Paid",0,$E3))
K4: =IF($A4="","",IF($H4="Paid",0,$E4))
K5: =IF($A5="","",IF($H5="Paid",0,$E5))
K6: =IF($A6="","",IF($H6="Paid",0,$E6))
K7: =IF($A7="","",IF($H7="Paid",0,$E7))
K8: =IF($A8="","",IF($H8="Paid",0,$E8))
K9: =IF($A9="","",IF($H9="Paid",0,$E9))
K10: =IF($A10="","",IF($H10="Paid",0,$E10))
K11: =IF($A11="","",IF($H11="Paid",0,$E11))
K12: =IF($A12="","",IF($H12="Paid",0,$E12))
K13: =IF($A13="","",IF($H13="Paid",0,$E13))
... K251: =IF($A251="","",IF($H251="Paid",0,$E251))

Sheet Project Meeting Notes
A1: Date | B1: Meeting type | C1: Attendees | D1: Discussion points | E1: Decisions made | F1: Action items | G1: Follow-up date | H1: Notes

Sheet Client FFE Report
A1: Room | B1: Item name | C1: Description | D1: Quantity | E1: Vendor | F1: Product link | G1: Final cost | H1: Approval status | I1: Image link | J1: Client notes
A2: ='Master FF&E Schedule'!B2 | B2: ='Master FF&E Schedule'!D2 | C2: ='Master FF&E Schedule'!E2 | D2: ='Master FF&E Schedule'!F2 | E2: ='Master FF&E Schedule'!K2 | F2: ='Master FF&E Schedule'!M2 | G2: ='Master FF&E Schedule'!T2 | H2: ='Master FF&E Schedule'!W2 | I2: ='Master FF&E Schedule'!AA2
A3: ='Master FF&E Schedule'!B3 | B3: ='Master FF&E Schedule'!D3 | C3: ='Master FF&E Schedule'!E3 | D3: ='Master FF&E Schedule'!F3 | E3: ='Master FF&E Schedule'!K3 | F3: ='Master FF&E Schedule'!M3 | G3: ='Master FF&E Schedule'!T3 | H3: ='Master FF&E Schedule'!W3 | I3: ='Master FF&E Schedule'!AA3
A4: ='Master FF&E Schedule'!B4 | B4: ='Master FF&E Schedule'!D4 | C4: ='Master FF&E Schedule'!E4 | D4: ='Master FF&E Schedule'!F4 | E4: ='Master FF&E Schedule'!K4 | F4: ='Master FF&E Schedule'!M4 | G4: ='Master FF&E Schedule'!T4 | H4: ='Master FF&E Schedule'!W4 | I4: ='Master FF&E Schedule'!AA4
A5: ='Master FF&E Schedule'!B5 | B5: ='Master FF&E Schedule'!D5 | C5: ='Master FF&E Schedule'!E5 | D5: ='Master FF&E Schedule'!F5 | E5: ='Master FF&E Schedule'!K5 | F5: ='Master FF&E Schedule'!M5 | G5: ='Master FF&E Schedule'!T5 | H5: ='Master FF&E Schedule'!W5 | I5: ='Master FF&E Schedule'!AA5
A6: ='Master FF&E Schedule'!B6 | B6: ='Master FF&E Schedule'!D6 | C6: ='Master FF&E Schedule'!E6 | D6: ='Master FF&E Schedule'!F6 | E6: ='Master FF&E Schedule'!K6 | F6: ='Master FF&E Schedule'!M6 | G6: ='Master FF&E Schedule'!T6 | H6: ='Master FF&E Schedule'!W6 | I6: ='Master FF&E Schedule'!AA6
A7: ='Master FF&E Schedule'!B7 | B7: ='Master FF&E Schedule'!D7 | C7: ='Master FF&E Schedule'!E7 | D7: ='Master FF&E Schedule'!F7 | E7: ='Master FF&E Schedule'!K7 | F7: ='Master FF&E Schedule'!M7 | G7: ='Master FF&E Schedule'!T7 | H7: ='Master FF&E Schedule'!W7 | I7: ='Master FF&E Schedule'!AA7
A8: ='Master FF&E Schedule'!B8 | B8: ='Master FF&E Schedule'!D8 | C8: ='Master FF&E Schedule'!E8 | D8: ='Master FF&E Schedule'!F8 | E8: ='Master FF&E Schedule'!K8 | F8: ='Master FF&E Schedule'!M8 | G8: ='Master FF&E Schedule'!T8 | H8: ='Master FF&E Schedule'!W8 | I8: ='Master FF&E Schedule'!AA8
