Workbook

Sheet Lists
A1: Room Types | B1: FFE Categories | C1: Order Statuses | D1: Approval Statuses | E1: Delivery Statuses | F1: Install Statuses | G1: Priorities | H1: Payment Statuses | I1: Project Types | J1: Project Statuses | K1: Billing Methods | L1: Yes/No | M1: Design Statuses | N1: Fixture Types | O1: Finish Types | P1: Surfaces | Q1: Vendor Types | R1: Budget Categories | S1: Damage Checks | T1: Approval Types | U1: Project Phases | V1: Task Statuses | W1: Task Categories | X1: Measurement Types | Y1: Trades | Z1: Meeting Types | AA1: PO Statuses | AB1: Room Names | AC1: Vendor Names
A2: Living Room | B2: Sofa | C2: Sourcing | D2: Not Sent | E2: Not Ordered | F2: Not Scheduled | G2: Low | H2: Draft | I2: Residential | J2: Inquiry | K2: Flat Fee | L2: Yes | M2: Not Started | N2: Lighting | O2: Paint | P2: Wall | Q2: Furniture | R2: Furniture | S2: Not Checked | T2: Furniture | U2: Consultation | V2: Not Started | W2: Design | X2: Room | Y2: General Contractor | Z2: Client Consultation | AA2: Not Ordered | AB2: Living Room | AC2: Article
A3: Bedroom | B3: Chair | C3: Option Selected | D3: Sent | E3: Ordered | F3: Scheduled | G3: Medium | H3: Sent | I3: Commercial | J3: Proposal | K3: Hourly | L3: No | M3: Concept | N3: Faucet | O3: Wallpaper | P3: Ceiling | Q3: Lighting | R3: Lighting | S3: Good Condition | T3: Finish | U3: Measurements | V3: In Progress | W3: Sourcing | X3: Wall | Y3: Painter | Z3: Vendor Meeting | AA3: Ordered | AB3: Master Bedroom | AC3: West Elm
A4: Kitchen | B4: Table | C4: Client Review | D4: Approved | E4: Shipped | F4: In Progress | G4: High | H4: Paid | I4: Office | J4: Active | K4: Percentage | M4: In Progress | N4: Sink | O4: Flooring | P4: Floor | Q4: Fabric | R4: Rugs | S4: Damaged | T4: Layout | U4: Concept Design | V4: Waiting on Client | W4: Purchasing | X4: Window | Y4: Electrician | Z4: Site Visit | AA4: Confirmed | AB4: Kitchen | AC4: CB2
A5: Bathroom | B5: Bed | C5: Approved | D5: Revisions Requested | E5: In Transit | F5: Installed | G5: Urgent | H5: Partially Paid | I5: Retail | J5: On Hold | K5: Hybrid | M5: Client Review | N5: Shower Fixture | O5: Tile | P5: Cabinet | Q5: Flooring | R5: Decor | S5: Missing Item | T5: Color Palette | U5: Sourcing | V5: Waiting on Vendor | W5: Client | X5: Door | Y5: Plumber | Z5: Installation Meeting | AA5: In Production | AB5: Dining Room | AC5: Visual Comfort
A6: Dining Room | B6: Rug | C6: Ordered | D6: Rejected | E6: Delivered | F6: Punch List | H6: Overdue | I6: Hospitality | J6: Completed | M6: Approved | N6: Tub | O6: Countertop | P6: Countertop | Q6: Tile | R6: Artwork | S6: Wrong Item | T6: Budget | U6: Client Approval | V6: Complete | W6: Vendor | X6: Cabinet | Y6: Flooring Installer | Z6: Contractor Meeting | AA6: Shipped | AB6: Home Office | AC6: Schoolhouse
A7: Entryway | B7: Lighting | C7: Shipped | D7: On Hold | E7: Delayed | F7: Complete | H7: Cancelled | I7: Staging | J7: Cancelled | M7: Complete | N7: Toilet | O7: Backsplash | P7: Shower Wall | Q7: Paint | R7: Window Treatments | T7: Purchase | U7: Purchasing | V7: Delayed | W7: Site | X7: Furniture Space | Y7: Tile Installer | Z7: Final Walkthrough | AA7: Delivered | AB7: Powder Room | AC7: Loloi
A8: Office | B8: Artwork | C8: Delivered | E8: Partial | F8: On Hold | H8: Unpaid | M8: On Hold | N8: Cabinet Hardware | O8: Cabinet Finish | P8: Backsplash | Q8: Wallpaper | R8: Flooring | T8: Vendor | U8: Construction | W8: Installation | X8: Rug Area | Y8: Wallpaper Installer | AA8: Delayed | AC8: Wolf / Sub-Zero
A9: Nursery | B9: Mirror | C9: Installed | E9: Cancelled | N9: Door Hardware | O9: Fabric | P9: Upholstery | Q9: Decor | R9: Paint/Wallcovering | T9: Design Concept | U9: Delivery | W9: Admin | X9: Lighting Location | Y9: Carpenter | AA9: Cancelled | AC9: Rejuvenation
A10: Outdoor | B10: Window Treatment | C10: Cancelled | N10: Appliance | O10: Trim | P10: Drapery | Q10: Hardware | R10: Contractor Labor | U10: Installation | W10: Other | Y10: Window Treatment Installer | AA10: Returned | AC10: Four Hands
A11: Commercial Space | B11: Hardware | C11: Backordered | N11: Electrical | O11: Stone | P11: Other | Q11: Contractor | R11: Installation | U11: Styling | Y11: Furniture Installer | AC11: Signature Hardware
A12: Other | B12: Plumbing Fixture | C12: Not Ordered | N12: Other | O12: Wood | Q12: Installer | R12: Shipping | U12: Final Reveal | Y12: Cleaner
B13: Appliance | C13: Confirmed | O13: Metal | Q13: Workroom | R13: Taxes | U13: Punch List | Y13: Other
B14: Decor | C14: In Production | O14: Other | Q14: Custom Furniture | R14: Design Fee
B15: Textile | C15: Delayed | Q15: Other | R15: Contingency
B16: Cabinetry | C16: Returned
B17: Flooring
B18: Wallcovering
B19: Other

Sheet 01 Welcome
B2: INTERIOR DESIGN · FF&E PROJECT TRACKER
B4: by Novality store · Furniture, Fixtures & Equipment Management · Excel + Google Sheets
B6: QUICK START GUIDE
B7: Step 1 | C7: Add client & project details | E7: Open the Client & Project Profile tab and fill in client name, project address, budget, dates, and designer info.
B8: Step 2 | C8: Add rooms / areas | E8: Go to Room List and list every room or zone in the project with budget allocations and priority.
B9: Step 3 | C9: Add FF&E items | E9: Use the Master FF&E Schedule to log every furniture, fixture, and equipment item with vendor, cost, and status.
B10: Step 4 | C10: Track budget, orders, approvals & delivery | E10: Update Budget Tracker, Purchase Orders, Client Approvals, and Delivery & Installation as the project progresses.
B11: Step 5 | C11: Use the Dashboard for overview | E11: The Project Dashboard auto-summarizes KPIs, spend, and status so you always know where the project stands.
B13: WHAT EACH TAB IS USED FOR
B14: Tab | C14: Purpose
B15: 01 Welcome | C15: You are here — instructions and how to use this workbook
B16: 02 Dashboard | C16: Live KPI cards, charts, and project health at a glance
B17: 03 Client Profile | C17: Client contact, project scope, budget, and contract details
B18: 04 Room List | C18: All rooms/areas with budget allocation and design status
B19: 05 Master FF&E | C19: Core schedule — every FF&E item with full cost & status tracking
B20: 06 Furniture | C20: Furniture-only focused schedule for quick reviews
B21: 07 Fixtures | C21: Lighting, plumbing, hardware, appliances, built-ins
B22: 08 Finishes | C22: Paint, tile, flooring, wallpaper, countertops, fabrics
B23: 09 Sourcing | C23: Compare product options before final selection
B24: 10 Vendors | C24: Supplier database with trade discounts and lead times
B25: 11 Budget | C25: Category-level budget vs estimated vs actual
... B39: 25 Punch List | C39: Printable final punch list
B41: HOW TO ENTER DATA
B42: • Replace sample data with your real project information — sample rows are examples only.
B43: • Always start a new row under the last entry; do not insert columns (formulas depend on column order).
B44: • Yellow / green / red cells are driven by conditional formatting based on status values — pick from dropdowns.
B45: • Currency fields use accounting format. Enter numbers only (no $ signs).
B46: • Dates should be entered as real dates (YYYY-MM-DD) so filters and overdue logic work.
B47: • Product links can be full URLs; they become clickable in Excel and Google Sheets.
B48: • Image Link column can hold a URL to a product photo or mood-board image.
B49: • On the Master FF&E tab, Total Cost and Final Cost calculate automatically from Quantity, Unit Cost, Tax, Shipping, and Discount.
B51: COLOR CODING EXPLANATION
B52: GREEN | C52: Complete / Approved / On budget / Good condition
B53: YELLOW | C53: Pending / In progress / Awaiting response
B54: RED | C54: Overdue / Over budget / Delayed / Damaged / Rejected
B55: GRAY | C55: Cancelled / On hold / Not started
B56: TEAL HEADERS | C56: Section labels and accent UI
B57: NAVY HEADERS | C57: Column headers on all schedule tabs
B59: DROPDOWN INSTRUCTIONS
B60: • Click any status, category, room, priority, or type cell — a dropdown arrow appears.
...

Sheet 02 Dashboard
B2: PROJECT DASHBOARD
B4: =CONCATENATE("Project: ",'03 Client Profile'!C10," | Client: ",'03 Client Profile'!C5," | Status: ",'03 Client Profile'!C18)
B6: TOTAL PROJECT BUDGET | C6: TOTAL ESTIMATED COST | D6: TOTAL ACTUAL COST | E6: REMAINING BUDGET | F6: BUDGET USED %
B7: ='03 Client Profile'!C16 | C7: =SUMIF('05 Master FF&E'!V:V,"<>Cancelled",'05 Master FF&E'!T:T) | D7: =SUMIF('05 Master FF&E'!V:V,"<>Cancelled",'05 Master FF&E'!T:T) | E7: =B7-C7 | F7: =IF(B7=0,0,C7/B7)
B9: ITEMS INSTALLED | C9: OVERDUE TASKS | D9: PENDING APPROVALS | E9: OPEN VENDOR ORDERS | F9: ITEMS NOT ORDERED | G9: DELIVERED NOT INSTALLED | H9: TOTAL ROOMS BUDGET | I9: ROOMS OVER BUDGET | J9: VENDORS ON FILE | K9: OPEN INVOICES
B10: =COUNTIF('05 Master FF&E'!Y5:Y500,"Installed")+COUNTIF('05 Master FF&E'!Y5:Y500,"Complete") | C10: =COUNTIFS('16 To-Do List'!F5:F200,"<"&TODAY(),'16 To-Do List'!G5:G200,"<>Complete") | D10: =COUNTIF('14 Client Approvals'!F5:F200,"Sent")+COUNTIF('05 Master FF&E'!W5:W500,"Sent") | E10: =COUNTIF('12 Purchase Orders'!J5:J200,"Ordered")+COUNTIF('12 Purchase Orders'!J5:J200,"Confirmed")+COUNTIF('12 Purchase Orders'!J5:J200,"In Production")+COUNTIF('12 Purchase Orders'!J5:J200,"Shipped") | F10: =COUNTIF('05 Master FF&E'!V5:V500,"Not Ordered")+COUNTIF('05 Master FF&E'!V5:V500,"Sourcing")+COUNTIF('05 Master FF&E'!V5:V500,"Option Selected") | G10: =COUNTIFS('05 Master FF&E'!X5:X500,"Delivered",'05 Master FF&E'!Y5:Y500,"<>Installed",'05 Master FF&E'!Y5:Y500,"<>Complete") | H10: =SUM('04 Room List'!F5:F200) | I10: =COUNTIF('04 Room List'!I5:I200,"<0") | J10: =COUNTA('10 Vendors'!A5:A200) | K10: =COUNTIF('19 Invoices'!H5:H200,"Sent")+COUNTIF('19 Invoices'!H5:H200,"Partially Paid")+COUNTIF('19 Invoices'!H5:H200,"Overdue")
B12: CHART DATA & VISUAL SUMMARIES
B14: Budget by Room
B15: Room | C15: Budget | D15: Actual
B16: ='04 Room List'!A5 | C16: ='04 Room List'!F5 | D16: ='04 Room List'!H5
B17: ='04 Room List'!A6 | C17: ='04 Room List'!F6 | D17: ='04 Room List'!H6
B18: ='04 Room List'!A7 | C18: ='04 Room List'!F7 | D18: ='04 Room List'!H7
B19: ='04 Room List'!A8 | C19: ='04 Room List'!F8 | D19: ='04 Room List'!H8
B20: ='04 Room List'!A9 | C20: ='04 Room List'!F9 | D20: ='04 Room List'!H9
B21: ='04 Room List'!A10 | C21: ='04 Room List'!F10 | D21: ='04 Room List'!H10
B24: Item Status Breakdown
B25: Status | C25: Count
B26: Sourcing | C26: =COUNTIF('05 Master FF&E'!V5:V500,"Sourcing")+COUNTIF('05 Master FF&E'!Y5:Y500,"Sourcing")
B27: Approved | C27: =COUNTIF('05 Master FF&E'!V5:V500,"Approved")+COUNTIF('05 Master FF&E'!Y5:Y500,"Approved")
B28: Ordered | C28: =COUNTIF('05 Master FF&E'!V5:V500,"Ordered")+COUNTIF('05 Master FF&E'!Y5:Y500,"Ordered")
B29: Shipped | C29: =COUNTIF('05 Master FF&E'!V5:V500,"Shipped")+COUNTIF('05 Master FF&E'!Y5:Y500,"Shipped")
B30: Delivered | C30: =COUNTIF('05 Master FF&E'!V5:V500,"Delivered")+COUNTIF('05 Master FF&E'!Y5:Y500,"Delivered")
B31: Installed | C31: =COUNTIF('05 Master FF&E'!V5:V500,"Installed")+COUNTIF('05 Master FF&E'!Y5:Y500,"Installed")
B32: Cancelled | C32: =COUNTIF('05 Master FF&E'!V5:V500,"Cancelled")+COUNTIF('05 Master FF&E'!Y5:Y500,"Cancelled")
B35: Category Spend
B36: Category | C36: Spend
B37: Sofa | C37: =SUMIF('05 Master FF&E'!C5:C500,"Sofa",'05 Master FF&E'!T5:T500)
B38: Chair | C38: =SUMIF('05 Master FF&E'!C5:C500,"Chair",'05 Master FF&E'!T5:T500)
B39: Table | C39: =SUMIF('05 Master FF&E'!C5:C500,"Table",'05 Master FF&E'!T5:T500)
B40: Bed | C40: =SUMIF('05 Master FF&E'!C5:C500,"Bed",'05 Master FF&E'!T5:T500)
B41: Rug | C41: =SUMIF('05 Master FF&E'!C5:C500,"Rug",'05 Master FF&E'!T5:T500)
B42: Lighting | C42: =SUMIF('05 Master FF&E'!C5:C500,"Lighting",'05 Master FF&E'!T5:T500)
B43: Appliance | C43: =SUMIF('05 Master FF&E'!C5:C500,"Appliance",'05 Master FF&E'!T5:T500)
B44: Artwork | C44: =SUMIF('05 Master FF&E'!C5:C500,"Artwork",'05 Master FF&E'!T5:T500)
B45: Hardware | C45: =SUMIF('05 Master FF&E'!C5:C500,"Hardware",'05 Master FF&E'!T5:T500)
B46: Plumbing Fixture | C46: =SUMIF('05 Master FF&E'!C5:C500,"Plumbing Fixture",'05 Master FF&E'!T5:T500)
B49: Delivery Status
B50: Status | C50: Count
B51: Not Ordered | C51: =COUNTIF('05 Master FF&E'!X5:X500,"Not Ordered")
B52: Ordered | C52: =COUNTIF('05 Master FF&E'!X5:X500,"Ordered")
...

Sheet 03 Client Profile
A1: CLIENT & PROJECT PROFILE
A2: Project summary — update these fields first · Novality store
B4: CLIENT INFORMATION | E4: FIELD GUIDE
B5: Client Name | C5: Alexandra Chen | E5: Gold cells are editable inputs.
B6: Client Email | C6: alexandra.chen@email.com | E6: Gray cells are labels — locked.
B7: Phone Number | C7: (555) 234-8890 | E7: Soft blue cells = locked formulas.
E8: Use dropdowns where provided.
B9: PROJECT DETAILS | E9: Budget feeds the Dashboard KPIs.
B10: Project Name | C10: Chen Residence Refresh | E10: Unprotect password: premium
B11: Project Address | C11: 482 Maple Lane, Portland, OR 97205 | E11: by Novality store
B12: Project Type | C12: Residential
B13: Design Style | C13: Modern Organic / Warm Minimalist
B14: Start Date | C14: 46082
B15: Target Completion | C15: 46295
B16: Total Budget | C16: 85000
B17: Designer Name | C17: Jordan Blake Studio
B18: Project Status | C18: Active
B19: Scope Summary | C19: Full FF&E package for living, primary suite, kitchen refresh, dining, powder room, and home office. Includes furniture, lighting, rugs, finishes, and installation coordination.
B20: Client Notes | C20: Prefers low-VOC finishes. Dog-friendly fabrics required in living areas. Traveling Aug 1–15 — no deliveries that window.
B23: CONTRACT & BILLING (OPTIONAL)
B24: Contract Signed | C24: Yes
B25: Deposit Paid | C25: Yes
B26: Design Package Selected | C26: Full Service FF&E
B27: Billing Method | C27: Hybrid
B28: Design Fee | C28: 12000
B29: Hourly Rate (if applicable) | C29: 175
B30: Retainer / Deposit Amount | C30: 4000

Sheet 04 Room List
A1: ROOM LIST / AREA TRACKER
A2: Organize the project by room — budgets roll up to the Dashboard · Novality store
A4: Room Name | B4: Room Type | C4: Floor/Level | D4: Square Footage | E4: Design Status | F4: Budget Allocation | G4: Estimated Spend | H4: Actual Spend | I4: Remaining Budget | J4: Priority Level | K4: Notes
A5: Living Room | B5: Living Room | C5: 1 | D5: 320 | E5: In Progress | F5: 15000 | G5: =IF(A5="","",SUMIF('05 Master FF&E'!B:B,A5,'05 Master FF&E'!T:T)) | H5: =IF(A5="","",SUMIFS('05 Master FF&E'!T:T,'05 Master FF&E'!B:B,A5,'05 Master FF&E'!V:V,"<>Cancelled")) | I5: =IF(A5="","",F5-H5) | J5: High | K5: Primary gathering space
A6: Master Bedroom | B6: Bedroom | C6: 2 | D6: 280 | E6: Concept | F6: 12000 | G6: =IF(A6="","",SUMIF('05 Master FF&E'!B:B,A6,'05 Master FF&E'!T:T)) | H6: =IF(A6="","",SUMIFS('05 Master FF&E'!T:T,'05 Master FF&E'!B:B,A6,'05 Master FF&E'!V:V,"<>Cancelled")) | I6: =IF(A6="","",F6-H6) | J6: High | K6: Ensuite suite
A7: Kitchen | B7: Kitchen | C7: 1 | D7: 220 | E7: Client Review | F7: 25000 | G7: =IF(A7="","",SUMIF('05 Master FF&E'!B:B,A7,'05 Master FF&E'!T:T)) | H7: =IF(A7="","",SUMIFS('05 Master FF&E'!T:T,'05 Master FF&E'!B:B,A7,'05 Master FF&E'!V:V,"<>Cancelled")) | I7: =IF(A7="","",F7-H7) | J7: Urgent | K7: Full remodel
A8: Dining Room | B8: Dining Room | C8: 1 | D8: 180 | E8: Approved | F8: 8000 | G8: =IF(A8="","",SUMIF('05 Master FF&E'!B:B,A8,'05 Master FF&E'!T:T)) | H8: =IF(A8="","",SUMIFS('05 Master FF&E'!T:T,'05 Master FF&E'!B:B,A8,'05 Master FF&E'!V:V,"<>Cancelled")) | I8: =IF(A8="","",F8-H8) | J8: Medium | K8: Formal dining
A9: Home Office | B9: Office | C9: 2 | D9: 140 | E9: Not Started | F9: 5000 | G9: =IF(A9="","",SUMIF('05 Master FF&E'!B:B,A9,'05 Master FF&E'!T:T)) | H9: =IF(A9="","",SUMIFS('05 Master FF&E'!T:T,'05 Master FF&E'!B:B,A9,'05 Master FF&E'!V:V,"<>Cancelled")) | I9: =IF(A9="","",F9-H9) | J9: Low | K9: Guest office convertible
A10: Powder Room | B10: Bathroom | C10: 1 | D10: 45 | E10: In Progress | F10: 3500 | G10: =IF(A10="","",SUMIF('05 Master FF&E'!B:B,A10,'05 Master FF&E'!T:T)) | H10: =IF(A10="","",SUMIFS('05 Master FF&E'!T:T,'05 Master FF&E'!B:B,A10,'05 Master FF&E'!V:V,"<>Cancelled")) | I10: =IF(A10="","",F10-H10) | J10: Medium | K10: Guest bath
G11: =IF(A11="","",SUMIF('05 Master FF&E'!B:B,A11,'05 Master FF&E'!T:T)) | H11: =IF(A11="","",SUMIFS('05 Master FF&E'!T:T,'05 Master FF&E'!B:B,A11,'05 Master FF&E'!V:V,"<>Cancelled")) | I11: =IF(A11="","",F11-H11)
G12: =IF(A12="","",SUMIF('05 Master FF&E'!B:B,A12,'05 Master FF&E'!T:T)) | H12: =IF(A12="","",SUMIFS('05 Master FF&E'!T:T,'05 Master FF&E'!B:B,A12,'05 Master FF&E'!V:V,"<>Cancelled")) | I12: =IF(A12="","",F12-H12)
G13: =IF(A13="","",SUMIF('05 Master FF&E'!B:B,A13,'05 Master FF&E'!T:T)) | H13: =IF(A13="","",SUMIFS('05 Master FF&E'!T:T,'05 Master FF&E'!B:B,A13,'05 Master FF&E'!V:V,"<>Cancelled")) | I13: =IF(A13="","",F13-H13)
G14: =IF(A14="","",SUMIF('05 Master FF&E'!B:B,A14,'05 Master FF&E'!T:T)) | H14: =IF(A14="","",SUMIFS('05 Master FF&E'!T:T,'05 Master FF&E'!B:B,A14,'05 Master FF&E'!V:V,"<>Cancelled")) | I14: =IF(A14="","",F14-H14)
G15: =IF(A15="","",SUMIF('05 Master FF&E'!B:B,A15,'05 Master FF&E'!T:T)) | H15: =IF(A15="","",SUMIFS('05 Master FF&E'!T:T,'05 Master FF&E'!B:B,A15,'05 Master FF&E'!V:V,"<>Cancelled")) | I15: =IF(A15="","",F15-H15)
G16: =IF(A16="","",SUMIF('05 Master FF&E'!B:B,A16,'05 Master FF&E'!T:T)) | H16: =IF(A16="","",SUMIFS('05 Master FF&E'!T:T,'05 Master FF&E'!B:B,A16,'05 Master FF&E'!V:V,"<>Cancelled")) | I16: =IF(A16="","",F16-H16)
G17: =IF(A17="","",SUMIF('05 Master FF&E'!B:B,A17,'05 Master FF&E'!T:T)) | H17: =IF(A17="","",SUMIFS('05 Master FF&E'!T:T,'05 Master FF&E'!B:B,A17,'05 Master FF&E'!V:V,"<>Cancelled")) | I17: =IF(A17="","",F17-H17)
G18: =IF(A18="","",SUMIF('05 Master FF&E'!B:B,A18,'05 Master FF&E'!T:T)) | H18: =IF(A18="","",SUMIFS('05 Master FF&E'!T:T,'05 Master FF&E'!B:B,A18,'05 Master FF&E'!V:V,"<>Cancelled")) | I18: =IF(A18="","",F18-H18)
G19: =IF(A19="","",SUMIF('05 Master FF&E'!B:B,A19,'05 Master FF&E'!T:T)) | H19: =IF(A19="","",SUMIFS('05 Master FF&E'!T:T,'05 Master FF&E'!B:B,A19,'05 Master FF&E'!V:V,"<>Cancelled")) | I19: =IF(A19="","",F19-H19)
G20: =IF(A20="","",SUMIF('05 Master FF&E'!B:B,A20,'05 Master FF&E'!T:T)) | H20: =IF(A20="","",SUMIFS('05 Master FF&E'!T:T,'05 Master FF&E'!B:B,A20,'05 Master FF&E'!V:V,"<>Cancelled")) | I20: =IF(A20="","",F20-H20)
G21: =IF(A21="","",SUMIF('05 Master FF&E'!B:B,A21,'05 Master FF&E'!T:T)) | H21: =IF(A21="","",SUMIFS('05 Master FF&E'!T:T,'05 Master FF&E'!B:B,A21,'05 Master FF&E'!V:V,"<>Cancelled")) | I21: =IF(A21="","",F21-H21)
G22: =IF(A22="","",SUMIF('05 Master FF&E'!B:B,A22,'05 Master FF&E'!T:T)) | H22: =IF(A22="","",SUMIFS('05 Master FF&E'!T:T,'05 Master FF&E'!B:B,A22,'05 Master FF&E'!V:V,"<>Cancelled")) | I22: =IF(A22="","",F22-H22)
... G34: =IF(A34="","",SUMIF('05 Master FF&E'!B:B,A34,'05 Master FF&E'!T:T)) | H34: =IF(A34="","",SUMIFS('05 Master FF&E'!T:T,'05 Master FF&E'!B:B,A34,'05 Master FF&E'!V:V,"<>Cancelled")) | I34: =IF(A34="","",F34-H34)
E36: TOTALS | F36: =SUM(F5:F34) | G36: =SUM(G5:G34) | H36: =SUM(H5:H34) | I36: =SUM(I5:I34)

Sheet 05 Master FF&E
A1: MASTER FF&E SCHEDULE
A2: Furniture, Fixtures & Equipment — the core project schedule · Novality store
A4: Item ID | B4: Room | C4: Category | D4: Item Name | E4: Description | F4: Quantity | G4: Dimensions | H4: Material | I4: Finish | J4: Color | K4: Vendor | L4: Brand | M4: Product Link | N4: SKU/Model | O4: Unit Cost | P4: Total Cost | Q4: Tax | R4: Shipping | S4: Discount | T4: Final Cost | U4: Lead Time (wks) | V4: Order Status | W4: Approval Status | X4: Delivery Status | Y4: Install Status | Z4: Notes | AA4: Image Link
A5: FFE-001 | B5: Living Room | C5: Sofa | D5: Performance Sofa | E5: 88" deep seat sofa | F5: 1 | G5: 88"W x 40"D x 34"H | H5: Performance fabric | I5: Natural oak legs | J5: Stone | K5: Article | L5: Sven | M5: https://example.com/sofa | N5: SV-88-ST | O5: 1899 | P5: =F5*O5 | Q5: 151.92 | R5: 150 | S5: 0 | T5: =P5+Q5+R5-S5 | U5: 6 | V5: Approved | W5: Approved | X5: Ordered | Y5: Not Scheduled | Z5: Client favorite
A6: FFE-002 | B6: Living Room | C6: Chair | D6: Accent Lounge Chair | E6: Swivel lounge chair | F6: 2 | G6: 30"W x 32"D x 32"H | H6: Boucle | I6: Black metal | J6: Ivory | K6: West Elm | L6: Orbit | M6: https://example.com/chair | N6: OR-IV | O6: 699 | P6: =F6*O6 | Q6: 111.84 | R6: 80 | S6: 50 | T6: =P6+Q6+R6-S6 | U6: 4 | V6: Approved | W6: Approved | X6: Shipped | Y6: Scheduled
A7: FFE-003 | B7: Living Room | C7: Table | D7: Coffee Table | E7: Marble top coffee table | F7: 1 | G7: 48"W x 28"D x 16"H | H7: Marble/Brass | I7: Brushed brass | J7: White marble | K7: CB2 | L7: Vista | M7: https://example.com/table | N7: VS-48 | O7: 899 | P7: =F7*O7 | Q7: 71.92 | R7: 100 | S7: 0 | T7: =P7+Q7+R7-S7 | U7: 5 | V7: Ordered | W7: Approved | X7: Ordered | Y7: Not Scheduled
A8: FFE-004 | B8: Living Room | C8: Rug | D8: Area Rug 9x12 | E8: Wool flatweave | F8: 1 | G8: 9' x 12' | H8: Wool | I8: Handwoven | J8: Ivory/Taupe | K8: Loloi | L8: Magnolia | M8: https://example.com/rug | N8: MG-912 | O8: 1299 | P8: =F8*O8 | Q8: 103.92 | R8: 75 | S8: 100 | T8: =P8+Q8+R8-S8 | U8: 3 | V8: Delivered | W8: Approved | X8: Delivered | Y8: Installed | Z8: Pad ordered separately
A9: FFE-005 | B9: Living Room | C9: Lighting | D9: Floor Lamp | E9: Arched brass floor lamp | F9: 1 | G9: 72"H | H9: Brass/Linen | I9: Antique brass | J9: Brass | K9: Rejuvenation | L9: Arc | M9: https://example.com/lamp | N9: AR-72 | O9: 449 | P9: =F9*O9 | Q9: 35.92 | R9: 40 | S9: 0 | T9: =P9+Q9+R9-S9 | U9: 2 | V9: Installed | W9: Approved | X9: Delivered | Y9: Installed
A10: FFE-006 | B10: Master Bedroom | C10: Bed | D10: Platform Bed King | E10: Upholstered platform bed | F10: 1 | G10: King | H10: Linen | I10: Natural | J10: Oatmeal | K10: Article | L10: Ceni | M10: https://example.com/bed | N10: CN-K | O10: 1499 | P10: =F10*O10 | Q10: 119.92 | R10: 200 | S10: 0 | T10: =P10+Q10+R10-S10 | U10: 8 | V10: Client Review | W10: Sent | X10: Not Ordered | Y10: Not Scheduled | Z10: Awaiting fabric confirmation
A11: FFE-007 | B11: Master Bedroom | C11: Lighting | D11: Pendant Pair | E11: Glass globe pendants | F11: 2 | G11: 10" dia | H11: Glass/Brass | I11: Clear glass | J11: Brass | K11: Schoolhouse | L11: Globe | M11: https://example.com/pendant | N11: GL-10 | O11: 279 | P11: =F11*O11 | Q11: 44.64 | R11: 50 | S11: 0 | T11: =P11+Q11+R11-S11 | U11: 4 | V11: Approved | W11: Approved | X11: Ordered | Y11: Not Scheduled
A12: FFE-008 | B12: Kitchen | C12: Appliance | D12: Range 36" | E12: Dual fuel range | F12: 1 | G12: 36"W | H12: Stainless | I12: Professional | J12: SS | K12: Wolf | L12: DF36450 | M12: https://example.com/range | N12: DF36450 | O12: 8999 | P12: =F12*O12 | Q12: 719.92 | R12: 350 | S12: 200 | T12: =P12+Q12+R12-S12 | U12: 12 | V12: Ordered | W12: Approved | X12: In Production | Y12: Not Scheduled | Z12: Rough-in required
A13: FFE-009 | B13: Kitchen | C13: Lighting | D13: Island Pendants | E13: Linear brass pendants x3 | F13: 3 | G13: 14"H | H13: Brass/Glass | I13: Aged brass | J13: Brass | K13: Visual Comfort | L13: Bryant | M13: https://example.com/island | N13: BR-14 | O13: 520 | P13: =F13*O13 | Q13: 124.8 | R13: 90 | S13: 0 | T13: =P13+Q13+R13-S13 | U13: 6 | V13: Approved | W13: Approved | X13: Ordered | Y13: Not Scheduled
A14: FFE-010 | B14: Dining Room | C14: Table | D14: Dining Table | E14: Oak extension table | F14: 1 | G14: 72-96"L x 40"W | H14: Oak | I14: White oak | J14: Natural | K14: Ethnicraft | L14: Bok | M14: https://example.com/dining | N14: BK-72 | O14: 2499 | P14: =F14*O14 | Q14: 199.92 | R14: 250 | S14: 0 | T14: =P14+Q14+R14-S14 | U14: 10 | V14: Sourcing | W14: Not Sent | X14: Not Ordered | Y14: Not Scheduled | Z14: Comparing 3 options
A15: FFE-011 | B15: Dining Room | C15: Chair | D15: Dining Chairs | E15: Upholstered dining chairs | F15: 6 | G15: 19"W x 22"D x 33"H | H15: Performance fabric | I15: Oak legs | J15: Sand | K15: Four Hands | L15: Haiden | M15: https://example.com/dchair | N15: HD-SN | O15: 349 | P15: =F15*O15 | Q15: 167.52 | R15: 120 | S15: 100 | T15: =P15+Q15+R15-S15 | U15: 8 | V15: Option Selected | W15: Not Sent | X15: Not Ordered | Y15: Not Scheduled
A16: FFE-012 | B16: Powder Room | C16: Plumbing Fixture | D16: Vessel Sink | E16: Stone vessel sink | F16: 1 | G16: 16" dia | H16: Marble | I16: Honed | J16: Carrara | K16: Signature Hardware | L16: Vessel | M16: https://example.com/sink | N16: VS-16 | O16: 389 | P16: =F16*O16 | Q16: 31.12 | R16: 45 | S16: 0 | T16: =P16+Q16+R16-S16 | U16: 3 | V16: Delivered | W16: Approved | X16: Delivered | Y16: Scheduled
A17: FFE-013 | B17: Home Office | C17: Chair | D17: Desk Chair | E17: Ergonomic task chair | F17: 1 | G17: Standard | H17: Mesh/Leather | I17: Black | J17: Black | K17: Herman Miller | L17: Aeron | M17: https://example.com/aeron | N17: AE-B | O17: 1395 | P17: =F17*O17 | Q17: 111.6 | R17: 0 | S17: 100 | T17: =P17+Q17+R17-S17 | U17: 2 | V17: Sourcing | W17: Not Sent | X17: Not Ordered | Y17: Not Scheduled | Z17: Budget check needed
A18: FFE-014 | B18: Living Room | C18: Artwork | D18: Large Abstract Canvas | E18: Commissioned abstract | F18: 1 | G18: 48" x 60" | H18: Canvas/Oil | I18: Gallery wrap | J18: Multi | K18: Local Artist | L18: Custom | M18: https://example.com/art | N18: CUST-01 | O18: 2200 | P18: =F18*O18 | Q18: 0 | R18: 75 | S18: 0 | T18: =P18+Q18+R18-S18 | U18: 8 | V18: Client Review | W18: Sent | X18: Not Ordered | Y18: Not Scheduled | Z18: Sketch approved
A19: FFE-015 | B19: Kitchen | C19: Hardware | D19: Cabinet Pulls | E19: Brass bar pulls 6" | F19: 24 | G19: 6" | H19: Solid brass | I19: Unlacquered | J19: Brass | K19: Rejuvenation | L19: Bin | M19: https://example.com/pulls | N19: BN-6 | O19: 18 | P19: =F19*O19 | Q19: 34.56 | R19: 25 | S19: 0 | T19: =P19+Q19+R19-S19 | U19: 2 | V19: Approved | W19: Approved | X19: Ordered | Y19: Not Scheduled
P20: =IF(F20="","",F20*O20) | T20: =IF(F20="","",P20+Q20+R20-S20)
P21: =IF(F21="","",F21*O21) | T21: =IF(F21="","",P21+Q21+R21-S21)
P22: =IF(F22="","",F22*O22) | T22: =IF(F22="","",P22+Q22+R22-S22)
P23: =IF(F23="","",F23*O23) | T23: =IF(F23="","",P23+Q23+R23-S23)
P24: =IF(F24="","",F24*O24) | T24: =IF(F24="","",P24+Q24+R24-S24)
P25: =IF(F25="","",F25*O25) | T25: =IF(F25="","",P25+Q25+R25-S25)
P26: =IF(F26="","",F26*O26) | T26: =IF(F26="","",P26+Q26+R26-S26)
P27: =IF(F27="","",F27*O27) | T27: =IF(F27="","",P27+Q27+R27-S27)
P28: =IF(F28="","",F28*O28) | T28: =IF(F28="","",P28+Q28+R28-S28)
P29: =IF(F29="","",F29*O29) | T29: =IF(F29="","",P29+Q29+R29-S29)
P30: =IF(F30="","",F30*O30) | T30: =IF(F30="","",P30+Q30+R30-S30)
P31: =IF(F31="","",F31*O31) | T31: =IF(F31="","",P31+Q31+R31-S31)
... P84: =IF(F84="","",F84*O84) | T84: =IF(F84="","",P84+Q84+R84-S84)
N86: TOTALS | O86: =SUM(O5:O84) | P86: =SUM(P5:P84) | Q86: =SUM(Q5:Q84) | R86: =SUM(R5:R84) | S86: =SUM(S5:S84) | T86: =SUM(T5:T84)

Sheet 06 Furniture
A1: FURNITURE SCHEDULE
A2: Furniture-only view — filtered from the broader FF&E program · Novality store
A4: Room | B4: Furniture Item | C4: Dimensions | D4: Quantity | E4: Vendor | F4: Product Link | G4: Fabric/Material | H4: Finish | I4: Cost | J4: Approval Status | K4: Order Status | L4: Delivery Date | M4: Install Date | N4: Notes
A5: Living Room | B5: Performance Sofa | C5: 88"W x 40"D x 34"H | D5: 1 | E5: Article | F5: https://example.com/sofa | G5: Performance fabric | H5: Natural oak legs | I5: 2200.92 | J5: Approved | K5: Approved | N5: Client favorite
A6: Living Room | B6: Accent Lounge Chair | C6: 30"W x 32"D x 32"H | D6: 2 | E6: West Elm | F6: https://example.com/chair | G6: Boucle | H6: Black metal | I6: 1539.84 | J6: Approved | K6: Approved
A7: Living Room | B7: Coffee Table | C7: 48"W x 28"D x 16"H | D7: 1 | E7: CB2 | F7: https://example.com/table | G7: Marble/Brass | H7: Brushed brass | I7: 1070.92 | J7: Approved | K7: Ordered
A8: Living Room | B8: Area Rug 9x12 | C8: 9' x 12' | D8: 1 | E8: Loloi | F8: https://example.com/rug | G8: Wool | H8: Handwoven | I8: 1377.92 | J8: Approved | K8: Delivered | N8: Pad ordered separately
A9: Master Bedroom | B9: Platform Bed King | C9: King | D9: 1 | E9: Article | F9: https://example.com/bed | G9: Linen | H9: Natural | I9: 1818.92 | J9: Sent | K9: Client Review | N9: Awaiting fabric confirmation
A10: Dining Room | B10: Dining Table | C10: 72-96"L x 40"W | D10: 1 | E10: Ethnicraft | F10: https://example.com/dining | G10: Oak | H10: White oak | I10: 2948.92 | J10: Not Sent | K10: Sourcing | N10: Comparing 3 options
A11: Dining Room | B11: Dining Chairs | C11: 19"W x 22"D x 33"H | D11: 6 | E11: Four Hands | F11: https://example.com/dchair | G11: Performance fabric | H11: Oak legs | I11: 2281.52 | J11: Not Sent | K11: Option Selected
A12: Home Office | B12: Desk Chair | C12: Standard | D12: 1 | E12: Herman Miller | F12: https://example.com/aeron | G12: Mesh/Leather | H12: Black | I12: 1406.6 | J12: Not Sent | K12: Sourcing | N12: Budget check needed

Sheet 07 Fixtures
A1: FIXTURES SCHEDULE
A2: Lighting, plumbing, hardware, appliances, and built-in fixtures · Novality store
A4: Room | B4: Fixture Type | C4: Item Name | D4: Finish | E4: Size | F4: Vendor | G4: Model/SKU | H4: Quantity | I4: Unit Cost | J4: Total Cost | K4: Required Rough-In Date | L4: Order Deadline | M4: Delivery Date | N4: Installer Notes
A5: Living Room | B5: Lighting | C5: Floor Lamp | D5: Antique brass | E5: 72"H | F5: Rejuvenation | G5: AR-72 | H5: 1 | I5: 449 | J5: =H5*I5
A6: Master Bedroom | B6: Lighting | C6: Pendant Pair | D6: Clear glass | E6: 10" dia | F6: Schoolhouse | G6: GL-10 | H6: 2 | I6: 279 | J6: =H6*I6
A7: Kitchen | B7: Appliance | C7: Range 36" | D7: Professional | E7: 36"W | F7: Wolf | G7: DF36450 | H7: 1 | I7: 8999 | J7: =H7*I7 | N7: Rough-in required
A8: Kitchen | B8: Lighting | C8: Island Pendants | D8: Aged brass | E8: 14"H | F8: Visual Comfort | G8: BR-14 | H8: 3 | I8: 520 | J8: =H8*I8
A9: Powder Room | B9: Faucet | C9: Vessel Sink | D9: Honed | E9: 16" dia | F9: Signature Hardware | G9: VS-16 | H9: 1 | I9: 389 | J9: =H9*I9
A10: Kitchen | B10: Cabinet Hardware | C10: Cabinet Pulls | D10: Unlacquered | E10: 6" | F10: Rejuvenation | G10: BN-6 | H10: 24 | I10: 18 | J10: =H10*I10
J11: =IF(H11="","",H11*I11)
J12: =IF(H12="","",H12*I12)
J13: =IF(H13="","",H13*I13)
J14: =IF(H14="","",H14*I14)
J15: =IF(H15="","",H15*I15)
J16: =IF(H16="","",H16*I16)
J17: =IF(H17="","",H17*I17)
J18: =IF(H18="","",H18*I18)
J19: =IF(H19="","",H19*I19)
J20: =IF(H20="","",H20*I20)
J21: =IF(H21="","",H21*I21)
J22: =IF(H22="","",H22*I22)
... J39: =IF(H39="","",H39*I39)

Sheet 08 Finishes
A1: FINISHES SCHEDULE
A2: Paint, tile, flooring, wallpaper, countertops, fabrics, and more · Novality store
A4: Room | B4: Surface/Application | C4: Finish Type | D4: Product Name | E4: Color/Finish | F4: Material | G4: Vendor | H4: Product Link | I4: SKU | J4: Quantity Needed | K4: Unit Cost | L4: Total Cost | M4: Sample Ordered | N4: Sample Approved | O4: Installer Notes
A5: Living Room | B5: Wall | C5: Paint | D5: Simply White OC-117 | E5: Simply White | F5: Latex | G5: Benjamin Moore | H5: https://example.com/paint | I5: OC-117 | J5: 5 | K5: 65 | L5: =J5*K5 | M5: Yes | N5: Yes | O5: Eggshell finish
A6: Living Room | B6: Floor | C6: Flooring | D6: White Oak Engineered | E6: Natural | F6: White Oak | G6: Wide Plank | H6: https://example.com/floor | I6: WO-7 | J6: 320 | K6: 12.5 | L6: =J6*K6 | M6: Yes | N6: Yes | O6: 7" width, matte
A7: Kitchen | B7: Countertop | C7: Countertop | D7: Calacatta Quartz | E7: Calacatta | F7: Quartz | G7: Caesarstone | H7: https://example.com/quartz | I7: 5143 | J7: 45 | K7: 85 | L7: =J7*K7 | M7: Yes | N7: Yes | O7: Mitered island edge
A8: Kitchen | B8: Backsplash | C8: Tile | D8: Handmade Zellige | E8: Warm White | F8: Ceramic | G8: Cle Tile | H8: https://example.com/zellige | I8: ZEL-WW | J8: 80 | K8: 28 | L8: =J8*K8 | M8: Yes | N8: Pending | O8: 2x6 vertical stack
A9: Master Bedroom | B9: Wall | C9: Paint | D9: Agreeable Gray | E9: Agreeable Gray | F9: Latex | G9: Sherwin Williams | H9: https://example.com/ag | I9: SW 7029 | J9: 3 | K9: 55 | L9: =J9*K9 | M9: Yes | N9: Yes | O9: Flat on walls
A10: Powder Room | B10: Wall | C10: Wallpaper | D10: Grasscloth Weave | E10: Natural Flax | F10: Grasscloth | G10: Phillip Jeffries | H10: https://example.com/pj | I10: PJ-4410 | J10: 6 | K10: 120 | L10: =J10*K10 | M10: Yes | N10: Yes | O10: Pre-pasted liner required
A11: Kitchen | B11: Cabinet | C11: Cabinet Finish | D11: Shaker Painted | E11: Soft White | F11: Maple | G11: Custom Millwork | I11: CM-SW | J11: 1 | K11: 8500 | L11: =J11*K11 | M11: No | N11: No | O11: Soft-close all doors
A12: Dining Room | B12: Drapery | C12: Fabric | D12: Linen Sheer | E12: Oatmeal | F12: Linen | G12: Romano | H12: https://example.com/linen | I12: LN-OAT | J12: 18 | K12: 42 | L12: =J12*K12 | M12: Yes | N12: Yes | O12: Double width panels
L13: =IF(J13="","",J13*K13)
L14: =IF(J14="","",J14*K14)
L15: =IF(J15="","",J15*K15)
L16: =IF(J16="","",J16*K16)
L17: =IF(J17="","",J17*K17)
L18: =IF(J18="","",J18*K18)
L19: =IF(J19="","",J19*K19)
L20: =IF(J20="","",J20*K20)
L21: =IF(J21="","",J21*K21)
L22: =IF(J22="","",J22*K22)
L23: =IF(J23="","",J23*K23)
L24: =IF(J24="","",J24*K24)
... L39: =IF(J39="","",J39*K39)

Sheet 09 Sourcing
A1: PRODUCT SOURCING TRACKER
A2: Compare options before locking the final FF&E selection · Novality store
A4: Room | B4: Item Needed | C4: Option 1 Link | D4: Option 1 Price | E4: Option 2 Link | F4: Option 2 Price | G4: Option 3 Link | H4: Option 3 Price | I4: Preferred Option | J4: Pros | K4: Cons | L4: Client Feedback | M4: Final Selection
A5: Dining Room | B5: Dining Table | C5: https://example.com/t1 | D5: 2499 | E5: https://example.com/t2 | F5: 1899 | G5: https://example.com/t3 | H5: 3200 | I5: Option 1 | J5: Solid oak, extends | K5: Long lead time | L5: Likes option 1 scale
A6: Master Bedroom | B6: Platform Bed | C6: https://example.com/b1 | D6: 1499 | E6: https://example.com/b2 | F6: 1799 | G6: https://example.com/b3 | H6: 1299 | I6: Option 1 | J6: Performance fabric | K6: Only 2 finishes | L6: Wants oatmeal | M6: Article Ceni King
A7: Home Office | B7: Desk Chair | C7: https://example.com/c1 | D7: 1395 | E7: https://example.com/c2 | F7: 850 | G7: https://example.com/c3 | H7: 450 | I7: Option 2 | J7: Good ergonomics, lower cost | K7: Less brand prestige | L7: Budget conscious
A8: Living Room | B8: Accent Chair | C8: https://example.com/a1 | D8: 699 | E8: https://example.com/a2 | F8: 899 | G8: https://example.com/a3 | H8: 549 | I8: Option 1 | J8: Swivel, boucle | K8: Shows pet hair | L8: Approved pair | M8: West Elm Orbit

Sheet 10 Vendors
A1: VENDOR & SUPPLIER DATABASE
A2: Trade accounts, discounts, and lead times in one place · Novality store
A4: Vendor Name | B4: Vendor Type | C4: Contact Person | D4: Email | E4: Phone | F4: Website | G4: Account Number | H4: Trade Discount % | I4: Lead Time | J4: Shipping Terms | K4: Return Policy | L4: Notes
A5: Article | B5: Furniture | C5: Sales Team | D5: trade@article.com | E5: 888-555-0101 | F5: https://article.com | G5: ART-4521 | H5: 0.15 | I5: 4-8 weeks | J5: Free over $999 | K5: 30 days unused | L5: Preferred furniture vendor
A6: West Elm | B6: Furniture | C6: Trade Desk | D6: trade@westelm.com | E6: 800-555-0102 | F6: https://westelm.com | G6: WE-8891 | H6: 0.2 | I6: 2-6 weeks | J6: Flat $99 | K6: 30 days | L6: Good for accents
A7: CB2 | B7: Furniture | C7: Trade | D7: trade@cb2.com | E7: 800-555-0103 | F7: https://cb2.com | G7: CB2-3310 | H7: 0.15 | I7: 3-6 weeks | J7: Varies | K7: 14 days
A8: Visual Comfort | B8: Lighting | C8: Rep: Jordan Lee | D8: jordan@vc.com | E8: 800-555-0104 | F8: https://visualcomfort.com | G8: VC-772 | H8: 0.4 | I8: 6-12 weeks | J8: FOB | K8: Special order no return | L8: Trade pricing excellent
A9: Schoolhouse | B9: Lighting | C9: Trade | D9: trade@schoolhouse.com | E9: 800-555-0105 | F9: https://schoolhouse.com | G9: SH-220 | H9: 0.2 | I9: 2-4 weeks | J9: Free over $150 | K9: 30 days
A10: Loloi | B10: Flooring | C10: Rep: Sam Park | D10: sam@loloi.com | E10: 800-555-0106 | F10: https://loloirugs.com | G10: LO-991 | H10: 0.25 | I10: 2-4 weeks | J10: Free over $500 | K10: 30 days | L10: Rug specialist
A11: Wolf / Sub-Zero | B11: Other | C11: Builder Sales | D11: builder@subzero.com | E11: 800-555-0107 | F11: https://subzero-wolf.com | G11: SZ-110 | H11: 0 | I11: 8-16 weeks | J11: Freight | K11: No return installed | L11: Appliances via dealer
A12: Rejuvenation | B12: Hardware | C12: Trade | D12: trade@rejuvenation.com | E12: 800-555-0108 | F12: https://rejuvenation.com | G12: RJ-554 | H12: 0.15 | I12: 1-3 weeks | J12: Free over $99 | K12: 30 days | L12: Hardware + lighting
A13: Four Hands | B13: Furniture | C13: Rep: Ava Kim | D13: ava@fourhands.com | E13: 800-555-0109 | F13: https://fourhands.com | G13: FH-440 | H13: 0.3 | I13: 6-10 weeks | J13: FOB warehouse | K13: Special order | L13: Showroom visit recommended
A14: Signature Hardware | B14: Hardware | C14: Trade | D14: trade@signaturehardware.com | E14: 800-555-0110 | F14: https://signaturehardware.com | G14: SIG-88 | H14: 0.1 | I14: 1-3 weeks | J14: Free over $99 | K14: 30 days | L14: Plumbing fixtures

Sheet 11 Budget
A1: BUDGET TRACKER
A2: Category-level budget control with auto totals and variance · Novality store
A4: Budget Category | B4: Budgeted Amount | C4: Estimated Amount | D4: Actual Amount | E4: Difference | F4: Paid Amount | G4: Balance Due | H4: Payment Status | I4: Notes
A5: Furniture | B5: 35000 | C5: =SUMIF('05 Master FF&E'!C:C,"Sofa",'05 Master FF&E'!T:T)+SUMIF('05 Master FF&E'!C:C,"Chair",'05 Master FF&E'!T:T)+SUMIF('05 Master FF&E'!C:C,"Table",'05 Master FF&E'!T:T)+SUMIF('05 Master FF&E'!C:C,"Bed",'05 Master FF&E'!T:T) | D5: =C5 | E5: =B5-D5 | F5: 0 | G5: =D5-F5 | H5: Unpaid
A6: Lighting | B6: 8000 | C6: =SUMIF('05 Master FF&E'!C:C,"Lighting",'05 Master FF&E'!T:T) | D6: =C6 | E6: =B6-D6 | F6: 0 | G6: =D6-F6 | H6: Unpaid
A7: Rugs | B7: 4000 | C7: =SUMIF('05 Master FF&E'!C:C,"Rug",'05 Master FF&E'!T:T) | D7: =C7 | E7: =B7-D7 | F7: 0 | G7: =D7-F7 | H7: Unpaid
A8: Decor | B8: 2500 | C8: 0 | D8: =C8 | E8: =B8-D8 | F8: 0 | G8: =D8-F8 | H8: Unpaid
A9: Artwork | B9: 3000 | C9: =SUMIF('05 Master FF&E'!C:C,"Artwork",'05 Master FF&E'!T:T) | D9: =C9 | E9: =B9-D9 | F9: 0 | G9: =D9-F9 | H9: Unpaid
A10: Window Treatments | B10: 4500 | C10: 0 | D10: =C10 | E10: =B10-D10 | F10: 0 | G10: =D10-F10 | H10: Unpaid
A11: Flooring | B11: 9000 | C11: 0 | D11: =C11 | E11: =B11-D11 | F11: 0 | G11: =D11-F11 | H11: Unpaid
A12: Paint/Wallcovering | B12: 2500 | C12: 0 | D12: =C12 | E12: =B12-D12 | F12: 0 | G12: =D12-F12 | H12: Unpaid
A13: Contractor Labor | B13: 5000 | C13: 0 | D13: =C13 | E13: =B13-D13 | F13: 0 | G13: =D13-F13 | H13: Unpaid
A14: Installation | B14: 2500 | C14: 0 | D14: =C14 | E14: =B14-D14 | F14: 0 | G14: =D14-F14 | H14: Unpaid
A15: Shipping | B15: 1500 | C15: =SUM('05 Master FF&E'!R5:R84) | D15: =C15 | E15: =B15-D15 | F15: 0 | G15: =D15-F15 | H15: Unpaid
A16: Taxes | B16: 4000 | C16: =SUM('05 Master FF&E'!Q5:Q84) | D16: =C16 | E16: =B16-D16 | F16: 0 | G16: =D16-F16 | H16: Unpaid
A17: Design Fee | B17: 12000 | C17: ='03 Client Profile'!C28 | D17: =C17 | E17: =B17-D17 | F17: 3600 | G17: =D17-F17 | H17: Partially Paid
A18: Contingency | B18: 5000 | C18: 0 | D18: =C18 | E18: =B18-D18 | F18: 0 | G18: =D18-F18 | H18: Unpaid
A19: TOTALS | B19: =SUM(B5:B18) | C19: =SUM(C5:C18) | D19: =SUM(D5:D18) | E19: =SUM(E5:E18) | F19: =SUM(F5:F18) | G19: =SUM(G5:G18)
A21: BUDGET SUMMARY
A22: Total Budget | B22: =B19
A23: Total Estimated | B23: =C19
A24: Total Actual | B24: =D19
A25: Over/Under Budget | B25: =B19-D19
A26: Remaining Balance Due | B26: =G19
A27: Total Paid | B27: =F19
A28: Paid vs Unpaid % | B28: =IF(D19=0,0,F19/D19)

Sheet 12 Purchase Orders
A1: PURCHASE ORDER / ORDER TRACKER
A2: Professional order log with tracking and payment status · Novality store
A4: PO Number | B4: Vendor | C4: Room | D4: Item | E4: Quantity | F4: Order Date | G4: Expected Ship Date | H4: Expected Delivery Date | I4: Actual Delivery Date | J4: Order Status | K4: Tracking Number | L4: Carrier | M4: Invoice Number | N4: Amount | O4: Paid Status | P4: Notes
A5: PO-1001 | B5: Article | C5: Living Room | D5: Performance Sofa | E5: 1 | F5: 46114 | G5: 46157 | H5: 46164 | J5: Ordered | L5: Freight | M5: INV-pending | N5: 2040.92 | O5: Unpaid
A6: PO-1002 | B6: West Elm | C6: Living Room | D6: Accent Lounge Chairs x2 | E6: 2 | F6: 46117 | G6: 46140 | H6: 46147 | J6: Shipped | K6: 1Z999AA10123456784 | L6: UPS | M6: INV-WE-8891 | N6: 1459.84 | O6: Paid
A7: PO-1003 | B7: Loloi | C7: Living Room | D7: Area Rug 9x12 | E7: 1 | F7: 46101 | G7: 46117 | H7: 46122 | I7: 46121 | J7: Delivered | K7: 1Z999BB | L7: FedEx | M7: INV-LO-220 | N7: 1377.92 | O7: Paid | P7: Pad separate
A8: PO-1004 | B8: Wolf / Sub-Zero | C8: Kitchen | D8: Range 36" | E8: 1 | F8: 46096 | G8: 46174 | H8: 46183 | J8: In Production | L8: Freight | N8: 9858.92 | O8: Partially Paid | P8: Deposit paid
A9: PO-1005 | B9: Visual Comfort | C9: Kitchen | D9: Island Pendants x3 | E9: 3 | F9: 46122 | G9: 46162 | H9: 46170 | J9: Confirmed | L9: UPS | N9: 1775.28 | O9: Unpaid
A10: PO-1006 | B10: Rejuvenation | C10: Kitchen | D10: Cabinet Pulls x24 | E10: 24 | F10: 46124 | G10: 46137 | H10: 46140 | J10: Ordered | L10: USPS | N10: 491.56 | O10: Unpaid
A11: PO-1007 | B11: Schoolhouse | C11: Master Bedroom | D11: Pendant Pair | E11: 2 | F11: 46120 | G11: 46143 | H11: 46150 | J11: Ordered | L11: UPS | N11: 652.64 | O11: Unpaid

Sheet 13 Delivery & Install
A1: DELIVERY & INSTALLATION TRACKER
A2: Keep every delivery and install coordinated and documented · Novality store
A4: Item | B4: Room | C4: Vendor | D4: Delivery Address | E4: Expected Delivery Date | F4: Actual Delivery Date | G4: Delivery Status | H4: Received By | I4: Damage Check | J4: Damage Notes | K4: Storage Location | L4: Install Date | M4: Installer | N4: Installation Status | O4: Punch List Notes
A5: Area Rug 9x12 | B5: Living Room | C5: Loloi | D5: 482 Maple Lane, Portland, OR | E5: 46122 | F5: 46121 | G5: Delivered | H5: J. Blake | I5: Good Condition | K5: On site living | L5: 46123 | M5: Studio Team | N5: Installed
A6: Accent Lounge Chairs | B6: Living Room | C6: West Elm | D6: 482 Maple Lane, Portland, OR | E6: 46147 | G6: Shipped | I6: Not Checked | K6: TBD | L6: 46154 | M6: Studio Team | N6: Scheduled
A7: Performance Sofa | B7: Living Room | C7: Article | D7: 482 Maple Lane, Portland, OR | E7: 46164 | G7: Ordered | I7: Not Checked | K7: TBD | L7: 46167 | M7: Article White Glove | N7: Not Scheduled | O7: Need elevator reservation
A8: Vessel Sink | B8: Powder Room | C8: Signature Hardware | D8: 482 Maple Lane, Portland, OR | E8: 46127 | F8: 46126 | G8: Delivered | H8: GC Lead | I8: Good Condition | K8: GC locked storage | L8: 46143 | M8: Plumber | N8: Scheduled
A9: Range 36" | B9: Kitchen | C9: Wolf / Sub-Zero | D9: 482 Maple Lane, Portland, OR | E9: 46183 | G9: Ordered | I9: Not Checked | K9: Dealer warehouse | L9: 46188 | M9: Appliance Installer | N9: Not Scheduled | O9: Confirm gas rough-in
A10: Floor Lamp | B10: Living Room | C10: Rejuvenation | D10: 482 Maple Lane, Portland, OR | E10: 46113 | F10: 46111 | G10: Delivered | H10: J. Blake | I10: Good Condition | K10: On site | L10: 46114 | M10: Studio Team | N10: Installed

Sheet 14 Client Approvals
A1: CLIENT APPROVAL TRACKER
A2: Every design decision and purchase sign-off in one place · Novality store
A4: Item/Design Decision | B4: Room | C4: Approval Type | D4: Sent to Client Date | E4: Client Response Date | F4: Status | G4: Approved Option | H4: Client Comments | I4: Revision Needed | J4: Final Approval Date
A5: Living room seating package | B5: Living Room | C5: Furniture | D5: 46099 | E5: 46103 | F5: Approved | G5: Article sofa + WE chairs | H5: Love the stone fabric | I5: No | J5: 46103
A6: Living room rug | B6: Living Room | C6: Furniture | D6: 46091 | E6: 46093 | F6: Approved | G6: Loloi Magnolia 9x12 | I6: No | J6: 46093
A7: Kitchen range selection | B7: Kitchen | C7: Purchase | D7: 46086 | E7: 46089 | F7: Approved | G7: Wolf DF36450 | H7: Proceed with stainless | I7: No | J7: 46089
A8: Primary bedroom bed | B8: Master Bedroom | C8: Furniture | D8: 46113 | F8: Sent | H8: Waiting on fabric sample photos | I8: Yes
A9: Dining table options | B9: Dining Room | C9: Furniture | D9: 46117 | F9: Sent | H9: Comparing 3 options in Sourcing tab | I9: Yes
A10: Overall color palette | B10: Living Room | C10: Color Palette | D10: 46073 | E10: 46078 | F10: Approved | G10: Warm neutrals + brass | H10: Approved board v2 | I10: No | J10: 46078
A11: Powder room wallpaper | B11: Powder Room | C11: Finish | D11: 46109 | E11: 46114 | F11: Approved | G11: Phillip Jeffries grasscloth | I11: No | J11: 46114
A12: Project budget confirmation | B12: — | C12: Budget | D12: 46068 | E12: 46071 | F12: Approved | G12: $85,000 total | H12: OK with contingency | I12: No | J12: 46071
A13: Concept presentation | B13: — | C13: Design Concept | D13: 46063 | E13: 46067 | F13: Approved | G13: Modern Organic concept | H13: Minor layout tweaks only | I13: No | J13: 46067

Sheet 15 Timeline
A1: PROJECT TIMELINE / GANTT TRACKER
A2: Phased plan with a simple week-by-week Gantt view (mark cells with X) · Novality store
A4: Phase | B4: Task | C4: Assigned To | D4: Start Date | E4: Due Date | F4: Completion Date | G4: Status | H4: Priority | I4: Dependencies | J4: Notes | K4: W1 | L4: W2 | M4: W3 | N4: W4 | O4: W5 | P4: W6 | Q4: W7 | R4: W8 | S4: W9 | T4: W10 | U4: W11 | V4: W12
A5: Consultation | B5: Kickoff meeting & questionnaire | C5: Jordan Blake | D5: 46082 | E5: 46084 | F5: 46084 | G5: Complete | H5: High | K5: █ | L5: █
A6: Measurements | B6: Site measure all rooms | C6: Studio Team | D6: 46086 | E6: 46088 | F6: 46088 | G6: Complete | H6: High | I6: Kickoff | L6: █
A7: Concept Design | B7: Mood boards & space plans | C7: Jordan Blake | D7: 46089 | E7: 46101 | F7: 46099 | G7: Complete | H7: High | I7: Measurements | L7: █ | M7: █ | N7: █
A8: Client Approval | B8: Concept presentation | C8: Jordan Blake | D8: 46101 | E8: 46106 | F8: 46103 | G8: Complete | H8: Urgent | I8: Concept Design | N8: █
A9: Sourcing | B9: Source living room package | C9: Studio Team | D9: 46106 | E9: 46127 | G9: In Progress | H9: High | I9: Concept approval | N9: █ | O9: █ | P9: █
A10: Sourcing | B10: Source kitchen fixtures & appliances | C10: Studio Team | D10: 46101 | E10: 46122 | F10: 46120 | G10: Complete | H10: Urgent | J10: Range ordered | N10: █ | O10: █
A11: Client Approval | B11: Approve primary suite furniture | C11: Client | D11: 46113 | E11: 46127 | G11: Waiting on Client | H11: High | I11: Sourcing | O11: █ | P11: █
A12: Purchasing | B12: Place living room POs | C12: Jordan Blake | D12: 46113 | E12: 46124 | F12: 46122 | G12: Complete | H12: High | I12: Approvals | O12: █ | P12: █
A13: Construction | B13: Kitchen rough-in coordination | C13: GC | D13: 46143 | E13: 46162 | G13: Not Started | H13: High | I13: Appliance order | R13: █ | S13: █
A14: Delivery | B14: Living room furniture delivery | C14: Vendors | D14: 46157 | E14: 46167 | G14: Not Started | H14: High | I14: POs | S14: █ | T14: █
A15: Installation | B15: Install living + powder | C15: Installers | D15: 46162 | E15: 46178 | G15: Not Started | H15: High | I15: Deliveries | S15: █ | T15: █ | U15: █
A16: Styling | B16: Final styling pass | C16: Jordan Blake | D16: 46183 | E16: 46188 | G16: Not Started | H16: Medium | I16: Installation | U16: █ | V16: █
A17: Final Reveal | B17: Client walkthrough | C17: Jordan Blake | D17: 46191 | E17: 46191 | G17: Not Started | H17: Urgent | I17: Styling | V17: █
A18: Punch List | B18: Complete punch items | C18: Studio + GC | D18: 46191 | E18: 46203 | G18: Not Started | H18: High | I18: Reveal | V18: █

Sheet 16 To-Do List
A1: TASK & TO-DO LIST
A2: Daily working list for the design team · Novality store
A4: Task | B4: Room | C4: Category | D4: Assigned To | E4: Priority | F4: Due Date | G4: Status | H4: Notes
A5: Email client fabric photos for primary bed | B5: Master Bedroom | C5: Client | D5: Jordan Blake | E5: High | F5: 46124 | G5: In Progress
A6: Confirm Wolf range rough-in dimensions with GC | B6: Kitchen | C6: Site | D6: Studio Team | E6: Urgent | F6: 46122 | G6: Waiting on Vendor | H6: Need GC response
A7: Order rug pad for living room | B7: Living Room | C7: Purchasing | D7: Studio Team | E7: Medium | F7: 46127 | G7: Not Started
A8: Schedule elevator for sofa delivery | B8: Living Room | C8: Installation | D8: Jordan Blake | E8: High | F8: 46152 | G8: Not Started | H8: Building mgmt 48h notice
A9: Update budget actuals after West Elm invoice | B9: — | C9: Admin | D9: Studio Team | E9: Medium | F9: 46120 | G9: Complete
A10: Request trade quote Four Hands dining chairs | B10: Dining Room | C10: Sourcing | D10: Studio Team | E10: High | F10: 46126 | G10: In Progress
A11: Send dining table options board to client | B11: Dining Room | C11: Client | D11: Jordan Blake | E11: High | F11: 46123 | G11: Waiting on Client | H11: Board sent 4/5
A12: Book site visit for powder install | B12: Powder Room | C12: Installation | D12: Studio Team | E12: Medium | F12: 46132 | G12: Not Started
A13: Collect paint touch-up kit from BM | B13: Living Room | C13: Vendor | D13: Studio Team | E13: Low | F13: 46142 | G13: Not Started
A14: Review overdue open POs | B14: — | C14: Purchasing | D14: Jordan Blake | E14: Urgent | F14: 46121 | G14: Delayed | H14: Check Visual Comfort

Sheet 17 Measurements
A1: MEASUREMENT LOG
A2: Field measurements for designers and installers · Novality store
A4: Room | B4: Measurement Type | C4: Width | D4: Height | E4: Depth | F4: Length | G4: Ceiling Height | H4: Window Size | I4: Door Size | J4: Wall Length | K4: Notes
A5: Living Room | B5: Room | C5: 18' | D5: 9' | E5: — | F5: 16' | G5: 9' | H5: — | I5: — | J5: — | K5: Open to dining
A6: Living Room | B6: Window | C6: 6' | D6: 5' | E6: — | F6: — | G6: — | H6: 6' x 5' | I6: — | J6: — | K6: South facing, 2 panels
A7: Living Room | B7: Rug Area | C7: 11' | D7: — | E7: — | F7: 14' | G7: — | H7: — | I7: — | J7: — | K7: Allow 12–18" border
A8: Master Bedroom | B8: Room | C8: 14' | D8: 9' | E8: — | F8: 16' | G8: 9' | H8: — | I8: — | J8: —
A9: Master Bedroom | B9: Furniture Space | C9: 80" | D9: — | E9: 84" | F9: — | G9: — | H9: — | I9: — | J9: — | K9: King bed wall
A10: Kitchen | B10: Room | C10: 12' | D10: 9' | E10: — | F10: 16' | G10: 9' | H10: — | I10: — | J10: — | K10: Island 8' x 3.5'
A11: Kitchen | B11: Cabinet | C11: 36" | D11: 36" | E11: 24" | F11: — | G11: — | H11: — | I11: — | J11: — | K11: Base run east wall
A12: Powder Room | B12: Room | C12: 5' | D12: 9' | E12: — | F12: 8' | G12: 9' | H12: — | I12: 28" door | J12: — | K12: Tight clearances
A13: Home Office | B13: Window | C13: 4' | D13: 5' | E13: — | F13: — | G13: — | H13: 4' x 5' | I13: — | J13: — | K13: Needs treatment
A14: Dining Room | B14: Room | C14: 12' | D14: 9' | E14: — | F14: 14' | G14: 9' | H14: — | I14: — | J14: — | K14: Chandelier center 6' from window wall

Sheet 18 Contractors
A1: CONTRACTOR / INSTALLER TRACKER
A2: Coordinate trades, quotes, insurance, and schedules · Novality store
A4: Contractor/Vendor Name | B4: Trade | C4: Contact | D4: Scope | E4: Quote Amount | F4: Start Date | G4: End Date | H4: Payment Status | I4: Insurance Received | J4: Contract Signed | K4: Notes
A5: Summit Build Co. | B5: General Contractor | C5: Mike Torres · 555-2001 | D5: Kitchen rough-in & coordination | E5: 8500 | F5: 46143 | G5: 46188 | H5: Partially Paid | I5: Yes | J5: Yes | K5: COI on file
A6: Lumen Electric | B6: Electrician | C6: Priya Nair · 555-2002 | D6: Island pendants + recessed | E6: 2200 | F6: 46152 | G6: 46160 | H6: Unpaid | I6: Yes | J6: Yes
A7: Cascade Plumbing | B7: Plumber | C7: Ed Walsh · 555-2003 | D7: Powder vessel sink install | E7: 980 | F7: 46143 | G7: 46145 | H7: Unpaid | I7: Yes | J7: Yes
A8: Oak & Stone Floors | B8: Flooring Installer | C8: Lee Cho · 555-2004 | D8: Living white oak install | E8: 4200 | F8: 46132 | G8: 46140 | H8: Paid | I8: Yes | J8: Yes | K8: Completed
A9: Paper & Paste | B9: Wallpaper Installer | C9: Nina Sol · 555-2005 | D9: Powder grasscloth | E9: 750 | F9: 46147 | G9: 46148 | H9: Unpaid | I9: Yes | J9: No | K9: Send contract
A10: White Glove Crew | B10: Furniture Installer | C10: Dispatch · 555-2006 | D10: Living room furniture set | E10: 450 | F10: 46167 | G10: 46167 | H10: Unpaid | I10: Yes | J10: Yes | K10: Article partner
A11: Fresh Coat Pros | B11: Painter | C11: Tom Rivera · 555-2007 | D11: Touch-ups post install | E11: 600 | F11: 46183 | G11: 46185 | H11: Unpaid | I11: No | J11: No | K11: Need COI

Sheet 19 Invoices
A1: INVOICE & PAYMENT TRACKER
A2: Client billing for design fees and reimbursable items · Novality store
A4: Invoice Number | B4: Invoice Date | C4: Client | D4: Description | E4: Amount | F4: Due Date | G4: Paid Date | H4: Payment Status | I4: Payment Method | J4: Notes
A5: INV-2026-01 | B5: 46082 | C5: Alexandra Chen | D5: Design retainer / deposit | E5: 4000 | F5: 46096 | G5: 46091 | H5: Paid | I5: ACH
A6: INV-2026-02 | B6: 46113 | C6: Alexandra Chen | D6: Concept design milestone | E6: 4000 | F6: 46127 | G6: 46124 | H6: Paid | I6: ACH
A7: INV-2026-03 | B7: 46143 | C7: Alexandra Chen | D7: Procurement milestone | E7: 4000 | F7: 46157 | H7: Sent | J7: Due mid-month
A8: INV-2026-04 | B8: 46106 | C8: Alexandra Chen | D8: Reimbursable: rug + pad | E8: 1378 | F8: 46120 | G8: 46117 | H8: Paid | I8: Credit Card
A9: INV-2026-05 | B9: 46127 | C9: Alexandra Chen | D9: Reimbursable: West Elm chairs | E9: 1460 | F9: 46142 | H9: Sent
A10: INV-2026-06 | B10: 46174 | C10: Alexandra Chen | D10: Final design fee balance | E10: 0 | F10: 46188 | H10: Draft | J10: Calculate at install
D36: TOTALS | E36: =SUM(E5:E34)
D37: Total Paid | E37: =SUMIF(H5:H34,"Paid",E5:E34)
D38: Outstanding | E38: =SUMIF(H5:H34,"Sent",E5:E34)+SUMIF(H5:H34,"Partially Paid",E5:E34)+SUMIF(H5:H34,"Overdue",E5:E34)

Sheet 20 Meeting Notes
A1: PROJECT NOTES / MEETING NOTES
A2: Consultations, vendor meetings, site visits, and walkthroughs · Novality store
A4: Date | B4: Meeting Type | C4: Attendees | D4: Discussion Points | E4: Decisions Made | F4: Action Items | G4: Follow-up Date | H4: Notes
A5: 46082 | B5: Client Consultation | C5: Alexandra Chen, Jordan Blake | D5: Goals, lifestyle, dog-friendly materials, budget $85k | E5: Proceed with full-service FF&E | F5: Send questionnaire; schedule measure | G5: 46084 | H5: Client loves warm minimalism
A6: 46088 | B6: Site Visit | C6: Jordan Blake, Studio Team | D6: Measured all rooms; noted powder door swing | E6: Use existing oak floors in living | F6: Draft plans; photo log | G6: 46091 | H6: Good natural light south
A7: 46103 | B7: Client Consultation | C7: Alexandra Chen, Jordan Blake | D7: Concept presentation — boards v2 | E7: Approved palette and living package | F7: Source dining table options | G7: 46117 | H7: Travel blackout Aug 1–15
A8: 46114 | B8: Vendor Meeting | C8: Jordan Blake, Article Trade | D8: Sofa lead times and white-glove | E8: Order Sven in Stone | F8: Send PO-1001 | G8: 46115 | H8: Trade 15% applied
A9: 46120 | B9: Contractor Meeting | C9: Mike Torres (GC), Jordan Blake | D9: Kitchen range rough-in & schedule | E9: Rough-in week of May 1 | F9: Confirm gas line size | G9: 46124 | H9: Need Wolf cut sheet

Sheet 21 Client FF&E Report
A1: CLIENT-FACING FF&E REPORT
A2: Print or PDF this sheet for client presentations · Novality store
A4: Item ID | B4: Room | C4: Category | D4: Item Name | E4: Quantity | F4: Vendor | G4: Finish/Color | H4: Unit Cost | I4: Total | J4: Status
A5: FFE-001 | B5: Living Room | C5: Sofa | D5: Performance Sofa | E5: 1 | F5: Article | G5: Natural oak legs / Stone | H5: 1899 | I5: 1899 | J5: Approved
A6: FFE-002 | B6: Living Room | C6: Chair | D6: Accent Lounge Chair | E6: 2 | F6: West Elm | G6: Black metal / Ivory | H6: 699 | I6: 1398 | J6: Approved
A7: FFE-003 | B7: Living Room | C7: Table | D7: Coffee Table | E7: 1 | F7: CB2 | G7: Brushed brass / White marble | H7: 899 | I7: 899 | J7: Approved
A8: FFE-004 | B8: Living Room | C8: Rug | D8: Area Rug 9x12 | E8: 1 | F8: Loloi | G8: Handwoven / Ivory/Taupe | H8: 1299 | I8: 1299 | J8: Approved
A9: FFE-005 | B9: Living Room | C9: Lighting | D9: Floor Lamp | E9: 1 | F9: Rejuvenation | G9: Antique brass / Brass | H9: 449 | I9: 449 | J9: Approved
A10: FFE-006 | B10: Master Bedroom | C10: Bed | D10: Platform Bed King | E10: 1 | F10: Article | G10: Natural / Oatmeal | H10: 1499 | I10: 1499 | J10: Sent
A11: FFE-007 | B11: Master Bedroom | C11: Lighting | D11: Pendant Pair | E11: 2 | F11: Schoolhouse | G11: Clear glass / Brass | H11: 279 | I11: 558 | J11: Approved
A12: FFE-008 | B12: Kitchen | C12: Appliance | D12: Range 36" | E12: 1 | F12: Wolf | G12: Professional / SS | H12: 8999 | I12: 8999 | J12: Approved
A13: FFE-009 | B13: Kitchen | C13: Lighting | D13: Island Pendants | E13: 3 | F13: Visual Comfort | G13: Aged brass / Brass | H13: 520 | I13: 1560 | J13: Approved
A14: FFE-010 | B14: Dining Room | C14: Table | D14: Dining Table | E14: 1 | F14: Ethnicraft | G14: White oak / Natural | H14: 2499 | I14: 2499 | J14: Not Sent
A15: FFE-011 | B15: Dining Room | C15: Chair | D15: Dining Chairs | E15: 6 | F15: Four Hands | G15: Oak legs / Sand | H15: 349 | I15: 2094 | J15: Not Sent
A16: FFE-012 | B16: Powder Room | C16: Plumbing Fixture | D16: Vessel Sink | E16: 1 | F16: Signature Hardware | G16: Honed / Carrara | H16: 389 | I16: 389 | J16: Approved
... A19: FFE-015 | B19: Kitchen | C19: Hardware | D19: Cabinet Pulls | E19: 24 | F19: Rejuvenation | G19: Unlacquered / Brass | H19: 18 | I19: 432 | J19: Approved
H20: TOTAL | I20: =SUM(I5:I19)

Sheet 22 Room Budget Report
A1: ROOM-BY-ROOM BUDGET REPORT
A2: Printable budget summary by area · Novality store
A4: Room | B4: Budget Allocation | C4: Estimated Spend | D4: Actual Spend | E4: Remaining | F4: % Used | G4: Status
A5: ='04 Room List'!A5 | B5: ='04 Room List'!F5 | C5: ='04 Room List'!G5 | D5: ='04 Room List'!H5 | E5: ='04 Room List'!I5 | F5: =IF(B5=0,0,D5/B5) | G5: ='04 Room List'!E5
A6: ='04 Room List'!A6 | B6: ='04 Room List'!F6 | C6: ='04 Room List'!G6 | D6: ='04 Room List'!H6 | E6: ='04 Room List'!I6 | F6: =IF(B6=0,0,D6/B6) | G6: ='04 Room List'!E6
A7: ='04 Room List'!A7 | B7: ='04 Room List'!F7 | C7: ='04 Room List'!G7 | D7: ='04 Room List'!H7 | E7: ='04 Room List'!I7 | F7: =IF(B7=0,0,D7/B7) | G7: ='04 Room List'!E7
A8: ='04 Room List'!A8 | B8: ='04 Room List'!F8 | C8: ='04 Room List'!G8 | D8: ='04 Room List'!H8 | E8: ='04 Room List'!I8 | F8: =IF(B8=0,0,D8/B8) | G8: ='04 Room List'!E8
A9: ='04 Room List'!A9 | B9: ='04 Room List'!F9 | C9: ='04 Room List'!G9 | D9: ='04 Room List'!H9 | E9: ='04 Room List'!I9 | F9: =IF(B9=0,0,D9/B9) | G9: ='04 Room List'!E9
A10: ='04 Room List'!A10 | B10: ='04 Room List'!F10 | C10: ='04 Room List'!G10 | D10: ='04 Room List'!H10 | E10: ='04 Room List'!I10 | F10: =IF(B10=0,0,D10/B10) | G10: ='04 Room List'!E10
A12: TOTAL | B12: =SUM(B5:B10) | C12: =SUM(C5:C10) | D12: =SUM(D5:D10) | E12: =SUM(E5:E10)

Sheet 23 Vendor Order Report
A1: VENDOR ORDER REPORT
A2: Printable open and completed orders by vendor · Novality store
A4: PO Number | B4: Vendor | C4: Item | D4: Qty | E4: Order Date | F4: Status | G4: Amount | H4: Paid Status | I4: Tracking
A5: ='12 Purchase Orders'!A5 | B5: ='12 Purchase Orders'!B5 | C5: ='12 Purchase Orders'!D5 | D5: ='12 Purchase Orders'!E5 | E5: ='12 Purchase Orders'!F5 | F5: ='12 Purchase Orders'!J5 | G5: ='12 Purchase Orders'!N5 | H5: ='12 Purchase Orders'!O5 | I5: ='12 Purchase Orders'!K5
A6: ='12 Purchase Orders'!A6 | B6: ='12 Purchase Orders'!B6 | C6: ='12 Purchase Orders'!D6 | D6: ='12 Purchase Orders'!E6 | E6: ='12 Purchase Orders'!F6 | F6: ='12 Purchase Orders'!J6 | G6: ='12 Purchase Orders'!N6 | H6: ='12 Purchase Orders'!O6 | I6: ='12 Purchase Orders'!K6
A7: ='12 Purchase Orders'!A7 | B7: ='12 Purchase Orders'!B7 | C7: ='12 Purchase Orders'!D7 | D7: ='12 Purchase Orders'!E7 | E7: ='12 Purchase Orders'!F7 | F7: ='12 Purchase Orders'!J7 | G7: ='12 Purchase Orders'!N7 | H7: ='12 Purchase Orders'!O7 | I7: ='12 Purchase Orders'!K7
